Workbook

Sheet Mode d'emploi
A1: Prévisions — budget, plan financier, prix et marges
A2: HEC GEMM Groupe 7 · Pôle Finance · Modèle vide créé le 27/10/2026, données à compléter
A4: Rubrique | B4: Contenu
A5: Objet | B5: Budget, plan financier, prix et marges (2 FINANCE/PREVISIONS/LISEZ-MOI.md).
A6: État du fichier | B6: Mis à jour le 27/10/2026 avec les données disponibles dans le dépôt (offre et prix du Produit, repères de marché du Marketing, coûts sourcés) et des hypothèses temporaires (H) pour les données manquantes. Liste des données manquantes et de ceux qui peuvent les fournir : 2 FINANCE/2026 1027 Données financières manquantes et hypothèses temporaires.md.
A7: Onglets | B7: « Prix et marges » : prix, coûts directs, marge, partage de la valeur et seuils d'une soirée, par offre. « Budget mensuel » : 12 mois (novembre 2026 à octobre 2027). « Prévu et réel » : à remplir dès le premier réel. « Plan financier 3 ans » : compte de résultat simplifié et besoin de financement.
A8: Offres modélisées | B8: Les trois soirées de l'offre A (Premier soir, Le Voyage, La Grande Nuit) et la privatisation de l'offre B avec un chef confirmé pour 10 convives, d'après 5 PRODUIT (offre, pricing, pilotes). Les prix y sont des propositions (P), non validées par l'équipe.
A9: Prévision et résultat | B9: Une prévision n'est pas un résultat : la comparer au réel dès qu'il est connu (onglet « Prévu et réel »), en citant la pièce du réel. Un objectif de chiffre d'affaires n'est pas une facture.
A10: Simplifications | B10: Prix affichés TTC convertis en HT avec un taux de TVA moyen (H). Ni impôt sur les sociétés, ni délais de paiement. Les acomptes et remboursements (seuil de 70 % à J-14) ne sont pas modélisés.
A11: Légende des cellules | B11: Cellule jaune, texte bleu : donnée à saisir. Cellule grise : formule, ne pas modifier. Texte vert : valeur reprise d'un autre onglet. Ligne verte « Exemple » : montre le format attendu, à remplacer ou supprimer.
A12: Colonne « Nature » | B12: F = fait constaté dans une pièce citée · I = inférence · P = proposition · H = hypothèse à valider (voir RULES.md). Si la pièce ne dit pas le chiffre : « non établi par les sources ».
A13: Colonne « Source » | B13: La pièce et l'endroit exact (ex. : S04, § Contexte, ou le nom de la note du dépôt). Signaler un chiffre tiré d'un argumentaire (plan d'affaires, présentation) plutôt que d'un document de gestion (facture, relevé, procès-verbal).
A14: Unités | B14: Montants en euros hors taxes, sauf mention contraire. Pourcentages saisis en % (ex. : 15 %).
A15: Cadre du projet | B15: Société d'événementiel : périodes vacantes de restaurants et de lieux avec cuisine, vivier de chefs d'exception, événements pour des communautés de foodies et pour des entreprises (privés éventuellement). Source : 1 DIRECTION/STRATEGIE/2026 1027 Descriptif du projet - Cadre de référence, décision D-01 du 27/10/2026.
A16: Références | B16: 2 FINANCE/PREVISIONS/LISEZ-MOI.md · 2 FINANCE/AGENT.md · RULES.md · 5 PRODUIT (offre, pricing, pilotes) · 3 MARKETING/new project (concurrence, communication)

Sheet Prix et marges
A1: Prix et marges d'une soirée
A2: Une offre par colonne. Lignes grises calculées. Montants HT sauf mention TTC.
A3: Valeurs du 27/10/2026 : prix et capacités proposés par le Produit (P) ; coûts en hypothèses temporaires (H), à remplacer par des devis.
A5: Poste | B5: Unité | C5: Premier soir (offre A) | D5: Le Voyage (offre A) | E5: La Grande Nuit (offre A) | F5: Privatisation, chef confirmé (offre B) | G5: Nature | H5: Source | I5: Fourni par
A6: 1. Recettes
A7: Capacité | B7: couverts | C7: 24 | D7: 24 | E7: 20 | F7: 10 | G7: P | H7: 5 PRODUIT/Fou d'un soir le pricing.md (@Fréd, 27/10/2026) ; offre B : exemple « table de 10 avec un chef confirmé », usage de l'hôte d'affaires (5 PRODUIT/Fou d'un soir l'offre.md) | I7: Produit
A8: Taux de remplissage | B8: % des couverts | C8: 0.8 | D8: 0.8 | E8: 0.8 | F8: 1 | G8: H | H8: Hypothèse temporaire. Seuil de confirmation proposé : 70 % des sièges vendus à J-14 (5 PRODUIT, plan des deux soirées pilotes) ; privatisation : groupe du client | I8: Finance
A9: Convives payants | B9: personnes | C9: =ROUND(C7*C8,0) -> 19 | D9: =ROUND(D7*D8,0) -> 19 | E9: =ROUND(E7*E8,0) -> 16 | F9: =ROUND(F7*F8,0) -> 10
A10: Prix affiché TTC par convive | B10: € TTC par personne | C10: 290 | D10: 420 | E10: 690 | F10: 300 | G10: P | H10: 5 PRODUIT/Fou d'un soir le pricing.md (@Fréd, 27/10/2026), prix des soirées et grille de privatisation (prix TTC tout compris) | I10: Produit
A11: Forfait affiché TTC par soirée (privatisation) | B11: € TTC | C11: 0 | D11: 0 | E11: 0 | F11: 6000 | G11: P | H11: 5 PRODUIT/Fou d'un soir le pricing.md (@Fréd, 27/10/2026), forfait de privatisation chef confirmé ; H : forfait supposé TTC comme les prix de l'offre A | I11: Produit
A12: Taux de TVA moyen | B12: % | C12: 0.12 | D12: 0.12 | E12: 0.12 | F12: 0.12 | G12: H | H12: Taux mixte (le pricing le signale « à vérifier avec la finance ») : 10 % sur la restauration, 20 % sur les boissons alcoolisées (règle fiscale à confirmer par un expert-comptable) ; H : boissons alcoolisées environ 20 % du prix | I12: Finance
A13: Prix HT par convive | B13: € HT par personne | C13: =C10/(1+C12) -> 258.92857 | D13: =D10/(1+D12) -> 375 | E13: =E10/(1+E12) -> 616.07143 | F13: =F10/(1+F12) -> 267.85714
A14: Forfait HT | B14: € HT | C14: =C11/(1+C12) -> 0 | D14: =D11/(1+D12) -> 0 | E14: =E11/(1+E12) -> 0 | F14: =F11/(1+F12) -> 5357.1429
A15: Minimum facturé (0 si aucun) | B15: € HT | C15: 0 | D15: 0 | E15: 0 | F15: 0 | G15: H | H15: Aucun minimum prévu par le Produit | I15: Produit
A16: Revenus complémentaires (partenariats, options) | B16: € HT | C16: 0 | D16: 0 | E16: 0 | F16: 0 | G16: H | H16: Non établi par les sources : partenariats vins et champagne envisagés, aucun accord | I16: Ventes
A17: Chiffre d'affaires de la soirée | B17: € HT | C17: =MAX(C9*C13+C14,C15)+C16 -> 4919.6429 | D17: =MAX(D9*D13+D14,D15)+D16 -> 7125 | E17: =MAX(E9*E13+E14,E15)+E16 -> 9857.1429 | F17: =MAX(F9*F13+F14,F15)+F16 -> 8035.7143
A18: 2. Coûts directs de la soirée
A19: Mise à disposition du lieu (restaurateur) | B19: € HT | C19: 1500 | D19: 1500 | E19: 2500 | F19: 2000 | G19: H | H19: F location de restaurants à Paris de 35 à 620 €/h, moyenne environ 373 à 386 €/h (Giggster) ; privatisation « à partir de 2 916 € » (Privateaser), cités dans 3 MARKETING/old project/MARCHE. La cible du Produit (11 à 12 % du prix HT) donnerait 750 à 1 350 € : écart signalé | I19: Ventes
A20: Chef : cachet et déplacement (part fixe) | B20: € HT | C20: 950 | D20: 2000 | E20: 3700 | F20: 1800 | G20: H | H20: Calé sur la répartition cible du Produit (chef 15 / 22 / 30 % du prix HT, P, 5 PRODUIT/Fou d'un soir le pricing.md (@Fréd, 27/10/2026)) ; F chef privé 500 à 1 400 € par jour hors matières (Chefs Talents 2026, cité dans 3 MARKETING/new project/3 Concurrence) | I20: Ventes
A21: Chef : part du chiffre d'affaires | B21: % du CA | C21: 0 | D21: 0 | E21: 0 | F21: 0 | G21: H | H21: Rémunération du chef supposée entièrement fixe ; une part variable reste possible (descriptif du projet 3, § 6) | I21: Ventes
A22: Rémunération du chef | B22: € HT | C22: =C20+C21*C17 -> 950 | D22: =D20+D21*D17 -> 2000 | E22: =E20+E21*E17 -> 3700 | F22: =F20+F21*F17 -> 1800
A23: Matières premières par convive | B23: € HT par personne | C23: 55 | D23: 70 | E23: 100 | F23: 50 | G23: H | H23: Calé sur la cible du Produit (matières et vins 33 / 30 / 27 % du prix HT, P) ; F ratio matières et boissons idéalement sous 35 % (Keobiz, cité dans le descriptif du projet 3) | I23: Opérations
A24: Vins ou jus d'accord par convive | B24: € HT par personne | C24: 30 | D24: 42 | E24: 66 | F24: 30 | G24: H | H24: Même source ; accord mets-jus au même coût que l'accord mets-vins (pricing : « coût réel reste à chiffrer ») | I24: Opérations
A25: Matières et boissons | B25: € HT | C25: =C9*(C23+C24) -> 1615 | D25: =D9*(D23+D24) -> 2128 | E25: =E9*(E23+E24) -> 2656 | F25: =F9*(F23+F24) -> 800
A26: Équipe de service et sommelier | B26: € HT | C26: 870 | D26: 1080 | E26: 1350 | F26: 950 | G26: H | H26: Calé sur la cible du Produit (équipe de service et sommelier 14 / 12 / 11 % du prix HT). Qui assure le service (restaurant ou nous) reste à décider (pricing, point 3) | I26: Opérations
A27: Ménage et remise en état du lieu | B27: € HT | C27: 150 | D27: 150 | E27: 150 | F27: 150 | G27: H | H27: Hypothèse temporaire ; cible « frais » du Produit 8 / 6 / 5 % du prix HT | I27: Opérations
A28: Assurance de la soirée | B28: € HT | C28: 150 | D28: 150 | E28: 150 | F28: 150 | G28: H | H28: Hypothèse temporaire, devis d'assureur à obtenir | I28: Juridique
A29: Décor, souvenir numéroté, petit matériel | B29: € HT | C29: 200 | D29: 250 | E29: 300 | F29: 150 | G29: H | H29: Hypothèse temporaire (menu numéroté, souvenir, mise en scène) | I29: Opérations
A30: Frais de paiement | B30: % du CA | C30: 0.016 | D30: 0.016 | E30: 0.016 | F30: 0 | G30: H | H30: F Stripe 1,5 % + 0,25 € par carte européenne (stripe.com/fr/pricing, consulté le 27/10/2026), arrondi à 1,6 % ; privatisation réglée par virement (H) | I30: Finance
A31: Commission d'apporteur (concierge, agence) | B31: % du CA | C31: 0 | D31: 0.05 | E31: 0.1 | F31: 0.1 | G31: H | H31: F honoraires d'agence 10 à 20 % du budget (BlackTrombone 2026, cité dans le descriptif du projet 3) ; part des ventes via les concierges à mesurer pendant les pilotes | I31: Marketing
A32: Frais et commissions | B32: € HT | C32: =(C30+C31)*C17 -> 78.714286 | D32: =(D30+D31)*D17 -> 470.25 | E32: =(E30+E31)*E17 -> 1143.4286 | F32: =(F30+F31)*F17 -> 803.57143
A33: Autres coûts directs (photographe) | B33: € HT | C33: 260 | D33: 260 | E33: 260 | F33: 0 | G33: H | H33: Photographe une demi-journée ; F tarif journalier 410 à 520 € (Malt, via Modèles de Business Plan, 15/09/2026) ; pas de photo en privatisation (confidentialité) | I33: Marketing
A34: Total des coûts directs | B34: € HT | C34: =C19+C22+C25+C26+C27+C28+C29+C32+C33 -> 5773.7143 | D34: =D19+D22+D25+D26+D27+D28+D29+D32+D33 -> 7988.25 | E34: =E19+E22+E25+E26+E27+E28+E29+E32+E33 -> 12209.429 | F34: =F19+F22+F25+F26+F27+F28+F29+F32+F33 -> 6803.5714
A35: 3. Marge, partage de la valeur et seuils
A36: Marge sur coûts directs | B36: € HT | C36: =C17-C34 -> -854.07143 | D36: =D17-D34 -> -863.25 | E36: =E17-E34 -> -2352.2857 | F36: =F17-F34 -> 1232.1429
A37: Taux de marge | B37: % du CA | C37: =IF(C17>0,C36/C17,0) -> -0.17360436 | D37: =IF(D17>0,D36/D17,0) -> -0.12115789 | E37: =IF(E17>0,E36/E17,0) -> -0.23863768 | F37: =IF(F17>0,F36/F17,0) -> 0.15333333
A38: Marge par convive payant | B38: € HT par personne | C38: =IF(C9>0,C36/C9,0) -> -44.951128 | D38: =IF(D9>0,D36/D9,0) -> -45.434211 | E38: =IF(E9>0,E36/E9,0) -> -147.01786 | F38: =IF(F9>0,F36/F9,0) -> 123.21429
A39: Part du lieu | B39: % du CA | C39: =IF(C17>0,C19/C17,0) -> 0.30490018 | D39: =IF(D17>0,D19/D17,0) -> 0.21052632 | E39: =IF(E17>0,E19/E17,0) -> 0.25362319 | F39: =IF(F17>0,F19/F17,0) -> 0.24888889
A40: Part du chef | B40: % du CA | C40: =IF(C17>0,C22/C17,0) -> 0.19310345 | D40: =IF(D17>0,D22/D17,0) -> 0.28070175 | E40: =IF(E17>0,E22/E17,0) -> 0.37536232 | F40: =IF(F17>0,F22/F17,0) -> 0.224
A41: Part de la société (marge) | B41: % du CA | C41: =C37 -> -0.17360436 | D41: =D37 -> -0.12115789 | E41: =E37 -> -0.23863768 | F41: =F37 -> 0.15333333
...

Sheet Budget mensuel
A1: Budget mensuel sur 12 mois
A2: Nombre de soirées et charges fixes saisis par mois ; recettes et coûts directs repris de l'onglet Prix et marges.
A3: Premier mois du budget (date) : | C3: 46327 | D3: H : préparation en novembre et décembre 2026, Premier soir en janvier 2027 (rétroplanning de 10 semaines des pilotes)
A5: Poste | B5: Total 12 mois | C5: =IF($C$3="","Mois "&(COLUMN()-2),EDATE($C$3,COLUMN()-3)) -> 46327 | D5: =IF($C$3="","Mois "&(COLUMN()-2),EDATE($C$3,COLUMN()-3)) -> 46357 | E5: =IF($C$3="","Mois "&(COLUMN()-2),EDATE($C$3,COLUMN()-3)) -> 46388 | F5: =IF($C$3="","Mois "&(COLUMN()-2),EDATE($C$3,COLUMN()-3)) -> 46419 | G5: =IF($C$3="","Mois "&(COLUMN()-2),EDATE($C$3,COLUMN()-3)) -> 46447 | H5: =IF($C$3="","Mois "&(COLUMN()-2),EDATE($C$3,COLUMN()-3)) -> 46478 | I5: =IF($C$3="","Mois "&(COLUMN()-2),EDATE($C$3,COLUMN()-3)) -> 46508 | J5: =IF($C$3="","Mois "&(COLUMN()-2),EDATE($C$3,COLUMN()-3)) -> 46539 | ... N5: =IF($C$3="","Mois "&(COLUMN()-2),EDATE($C$3,COLUMN()-3)) -> 46661 | O5: Nature | P5: Source
A6: Activité (nombre de soirées)
A7: Premier soir | B7: =SUM(C7:N7) -> 3 | C7: 0 | D7: 0 | E7: 1 | F7: 0 | G7: 0 | H7: 1 | I7: 0 | J7: 0 | K7: 1 | L7: 0 | M7: 0 | N7: 0 | O7: H | P7: H : une soirée de l'offre A par mois (5 PRODUIT, offre, « Rythme et unicité ») ; pilotes Premier soir puis La Grande Nuit à cinq semaines d'écart (plan des pilotes)
A8: Le Voyage | B8: =SUM(C8:N8) -> 3 | C8: 0 | D8: 0 | E8: 0 | F8: 0 | G8: 1 | H8: 0 | I8: 0 | J8: 1 | K8: 0 | L8: 0 | M8: 0 | N8: 1 | O8: H | P8: H : une soirée de l'offre A par mois (5 PRODUIT, offre, « Rythme et unicité ») ; pilotes Premier soir puis La Grande Nuit à cinq semaines d'écart (plan des pilotes)
A9: La Grande Nuit | B9: =SUM(C9:N9) -> 3 | C9: 0 | D9: 0 | E9: 0 | F9: 1 | G9: 0 | H9: 0 | I9: 1 | J9: 0 | K9: 0 | L9: 0 | M9: 1 | N9: 0 | O9: H | P9: H : une soirée de l'offre A par mois (5 PRODUIT, offre, « Rythme et unicité ») ; pilotes Premier soir puis La Grande Nuit à cinq semaines d'écart (plan des pilotes)
A10: Privatisations (chef confirmé) | B10: =SUM(C10:N10) -> 7 | C10: 0 | D10: 0 | E10: 0 | F10: 0 | G10: 0 | H10: 1 | I10: 1 | J10: 1 | K10: 0 | L10: 0 | M10: 2 | N10: 2 | O10: H | P10: H : privatisations après la décision de S+7 ; 2 par mois en septembre et octobre, période la plus demandée (F Prestagency, cité dans le descriptif du projet 3) ; août sans soirée
A11: Nombre total de soirées | B11: =SUM(C11:N11) -> 16 | C11: =SUM(C7:C10) -> 0 | D11: =SUM(D7:D10) -> 0 | E11: =SUM(E7:E10) -> 1 | F11: =SUM(F7:F10) -> 1 | G11: =SUM(G7:G10) -> 1 | H11: =SUM(H7:H10) -> 2 | I11: =SUM(I7:I10) -> 2 | J11: =SUM(J7:J10) -> 2 | ... N11: =SUM(N7:N10) -> 3
A12: Chiffre d'affaires et marge
A13: Chiffre d'affaires | B13: =SUM(C13:N13) -> 121955.36 | C13: =C7*'Prix et marges'!$C$17+C8*'Prix et marges'!$D$17+C9*'Prix et marges'!$E$17+C10*'Prix et marges'!$F$17 -> 0 | D13: =D7*'Prix et marges'!$C$17+D8*'Prix et marges'!$D$17+D9*'Prix et marges'!$E$17+D10*'Prix et marges'!$F$17 -> 0 | E13: =E7*'Prix et marges'!$C$17+E8*'Prix et marges'!$D$17+E9*'Prix et marges'!$E$17+E10*'Prix et marges'!$F$17 -> 4919.6429 | F13: =F7*'Prix et marges'!$C$17+F8*'Prix et marges'!$D$17+F9*'Prix et marges'!$E$17+F10*'Prix et marges'!$F$17 -> 9857.1429 | G13: =G7*'Prix et marges'!$C$17+G8*'Prix et marges'!$D$17+G9*'Prix et marges'!$E$17+G10*'Prix et marges'!$F$17 -> 7125 | H13: =H7*'Prix et marges'!$C$17+H8*'Prix et marges'!$D$17+H9*'Prix et marges'!$E$17+H10*'Prix et marges'!$F$17 -> 12955.357 | I13: =I7*'Prix et marges'!$C$17+I8*'Prix et marges'!$D$17+I9*'Prix et marges'!$E$17+I10*'Prix et marges'!$F$17 -> 17892.857 | J13: =J7*'Prix et marges'!$C$17+J8*'Prix et marges'!$D$17+J9*'Prix et marges'!$E$17+J10*'Prix et marges'!$F$17 -> 15160.714 | ... N13: =N7*'Prix et marges'!$C$17+N8*'Prix et marges'!$D$17+N9*'Prix et marges'!$E$17+N10*'Prix et marges'!$F$17 -> 23196.429
A14: Coûts directs | B14: =SUM(C14:N14) -> 125539.18 | C14: =C7*'Prix et marges'!$C$34+C8*'Prix et marges'!$D$34+C9*'Prix et marges'!$E$34+C10*'Prix et marges'!$F$34 -> 0 | D14: =D7*'Prix et marges'!$C$34+D8*'Prix et marges'!$D$34+D9*'Prix et marges'!$E$34+D10*'Prix et marges'!$F$34 -> 0 | E14: =E7*'Prix et marges'!$C$34+E8*'Prix et marges'!$D$34+E9*'Prix et marges'!$E$34+E10*'Prix et marges'!$F$34 -> 5773.7143 | F14: =F7*'Prix et marges'!$C$34+F8*'Prix et marges'!$D$34+F9*'Prix et marges'!$E$34+F10*'Prix et marges'!$F$34 -> 12209.429 | G14: =G7*'Prix et marges'!$C$34+G8*'Prix et marges'!$D$34+G9*'Prix et marges'!$E$34+G10*'Prix et marges'!$F$34 -> 7988.25 | H14: =H7*'Prix et marges'!$C$34+H8*'Prix et marges'!$D$34+H9*'Prix et marges'!$E$34+H10*'Prix et marges'!$F$34 -> 12577.286 | I14: =I7*'Prix et marges'!$C$34+I8*'Prix et marges'!$D$34+I9*'Prix et marges'!$E$34+I10*'Prix et marges'!$F$34 -> 19013 | J14: =J7*'Prix et marges'!$C$34+J8*'Prix et marges'!$D$34+J9*'Prix et marges'!$E$34+J10*'Prix et marges'!$F$34 -> 14791.821 | ... N14: =N7*'Prix et marges'!$C$34+N8*'Prix et marges'!$D$34+N9*'Prix et marges'!$E$34+N10*'Prix et marges'!$F$34 -> 21595.393
A15: Marge sur coûts directs | B15: =SUM(C15:N15) -> -3583.8214 | C15: =C13-C14 -> 0 | D15: =D13-D14 -> 0 | E15: =E13-E14 -> -854.07143 | F15: =F13-F14 -> -2352.2857 | G15: =G13-G14 -> -863.25 | H15: =H13-H14 -> 378.07143 | I15: =I13-I14 -> -1120.1429 | J15: =J13-J14 -> 368.89286 | ... N15: =N13-N14 -> 1601.0357
A16: Charges fixes
A17: Salaires et charges sociales | B17: =SUM(C17:N17) -> 0 | C17: 0 | D17: 0 | E17: 0 | F17: 0 | G17: 0 | H17: 0 | I17: 0 | J17: 0 | K17: 0 | L17: 0 | M17: 0 | N17: 0 | O17: H | P17: H : fondateurs non rémunérés la première année
A18: Locaux et bureaux | B18: =SUM(C18:N18) -> 0 | C18: 0 | D18: 0 | E18: 0 | F18: 0 | G18: 0 | H18: 0 | I18: 0 | J18: 0 | K18: 0 | L18: 0 | M18: 0 | N18: 0 | O18: H | P18: H : pas de bureaux, travail à distance
A19: Logiciels et outils (site, billetterie, CRM) | B19: =SUM(C19:N19) -> 960 | C19: 80 | D19: 80 | E19: 80 | F19: 80 | G19: 80 | H19: 80 | I19: 80 | J19: 80 | K19: 80 | L19: 80 | M19: 80 | N19: 80 | O19: H | P19: H : site, billetterie et fichier clients ; devis à obtenir
A20: Marketing et communication | B20: =SUM(C20:N20) -> 7200 | C20: 300 | D20: 1500 | E20: 1500 | F20: 1500 | G20: 300 | H20: 300 | I20: 300 | J20: 300 | K20: 300 | L20: 300 | M20: 300 | N20: 300 | O20: H | P20: H : 300 €/mois (contenus, cartes, coffrets) + 3 dîners de concierges à 1 200 € (2 à 3 dîners prévus par 3 MARKETING/new project/4 Communication)
A21: Assurance responsabilité civile professionnelle | B21: =SUM(C21:N21) -> 600 | C21: 50 | D21: 50 | E21: 50 | F21: 50 | G21: 50 | H21: 50 | I21: 50 | J21: 50 | K21: 50 | L21: 50 | M21: 50 | N21: 50 | O21: H | P21: F 200 à 300 €/an pour une start-up en amorçage (Coover 2026) ; H : doublé pour une activité d'événements, devis à demander
A22: Honoraires (comptable, juridique) | B22: =SUM(C22:N22) -> 2700 | C22: 1600 | D22: 100 | E22: 100 | F22: 100 | G22: 100 | H22: 100 | I22: 100 | J22: 100 | K22: 100 | L22: 100 | M22: 100 | N22: 100 | O22: H | P22: H : expert-comptable 100 €/mois ; contrats types lieux, chefs et clients 1 500 € en novembre
A23: Banque | B23: =SUM(C23:N23) -> 360 | C23: 30 | D23: 30 | E23: 30 | F23: 30 | G23: 30 | H23: 30 | I23: 30 | J23: 30 | K23: 30 | L23: 30 | M23: 30 | N23: 30 | O23: H | P23: H : compte professionnel et terminal de paiement
A24: Déplacements | B24: =SUM(C24:N24) -> 600 | C24: 50 | D24: 50 | E24: 50 | F24: 50 | G24: 50 | H24: 50 | I24: 50 | J24: 50 | K24: 50 | L24: 50 | M24: 50 | N24: 50 | O24: H | P24: H : repérage des lieux et rendez-vous
A25: Autres charges (création de la société) | B25: =SUM(C25:N25) -> 252 | C25: 252 | D25: 0 | E25: 0 | F25: 0 | G25: 0 | H25: 0 | I25: 0 | J25: 0 | K25: 0 | L25: 0 | M25: 0 | N25: 0 | O25: F | P25: Création d'une SAS : 252 € (immatriculation, annonce légale, bénéficiaires effectifs ; LegalPlace, 06/08/2026, cité dans PRODUCTIONS ASSISTANTS/2026 1027 Synthèse marketing…)
A26: Total des charges fixes | B26: =SUM(C26:N26) -> 12672 | C26: =SUM(C17:C25) -> 2362 | D26: =SUM(D17:D25) -> 1810 | E26: =SUM(E17:E25) -> 1810 | F26: =SUM(F17:F25) -> 1810 | G26: =SUM(G17:G25) -> 610 | H26: =SUM(H17:H25) -> 610 | I26: =SUM(I17:I25) -> 610 | J26: =SUM(J17:J25) -> 610 | ... N26: =SUM(N17:N25) -> 610
A27: Résultat
A28: Résultat d'exploitation du mois | B28: =SUM(C28:N28) -> -16255.821 | C28: =C15-C26 -> -2362 | D28: =D15-D26 -> -1810 | E28: =E15-E26 -> -2664.0714 | F28: =F15-F26 -> -4162.2857 | G28: =G15-G26 -> -1473.25 | H28: =H15-H26 -> -231.92857 | I28: =I15-I26 -> -1730.1429 | J28: =J15-J26 -> -241.10714 | ... N28: =N15-N26 -> 991.03571
A29: Résultat cumulé | B29: =N29 -> -16255.821 | C29: =C28 -> -2362 | D29: =C29+D28 -> -4172 | E29: =D29+E28 -> -6836.0714 | F29: =E29+F28 -> -10998.357 | G29: =F29+G28 -> -12471.607 | H29: =G29+H28 -> -12703.536 | I29: =H29+I28 -> -14433.679 | J29: =I29+J28 -> -14674.786 | K29: =J29+K28 -> -16138.857 | ... N29: =M29+N28 -> -16255.821

Sheet Prévu et réel
A1: Prévu et réel, mois par mois
A2: Le prévu vient du budget mensuel ; saisir le réel dès qu'il est connu, avec sa pièce. Aucun réel au 27/10/2026.
A5: Indicateur | B5: Total 12 mois | C5: =IF('Budget mensuel'!$C$3="","Mois "&(COLUMN()-2),EDATE('Budget mensuel'!$C$3,COLUMN()-3)) -> 46327 | D5: =IF('Budget mensuel'!$C$3="","Mois "&(COLUMN()-2),EDATE('Budget mensuel'!$C$3,COLUMN()-3)) -> 46357 | E5: =IF('Budget mensuel'!$C$3="","Mois "&(COLUMN()-2),EDATE('Budget mensuel'!$C$3,COLUMN()-3)) -> 46388 | F5: =IF('Budget mensuel'!$C$3="","Mois "&(COLUMN()-2),EDATE('Budget mensuel'!$C$3,COLUMN()-3)) -> 46419 | G5: =IF('Budget mensuel'!$C$3="","Mois "&(COLUMN()-2),EDATE('Budget mensuel'!$C$3,COLUMN()-3)) -> 46447 | H5: =IF('Budget mensuel'!$C$3="","Mois "&(COLUMN()-2),EDATE('Budget mensuel'!$C$3,COLUMN()-3)) -> 46478 | I5: =IF('Budget mensuel'!$C$3="","Mois "&(COLUMN()-2),EDATE('Budget mensuel'!$C$3,COLUMN()-3)) -> 46508 | J5: =IF('Budget mensuel'!$C$3="","Mois "&(COLUMN()-2),EDATE('Budget mensuel'!$C$3,COLUMN()-3)) -> 46539 | ... N5: =IF('Budget mensuel'!$C$3="","Mois "&(COLUMN()-2),EDATE('Budget mensuel'!$C$3,COLUMN()-3)) -> 46661
A6: Nombre de soirées
A7: Prévu | B7: =SUM(C7:N7) -> 16 | C7: ='Budget mensuel'!C11 -> 0 | D7: ='Budget mensuel'!D11 -> 0 | E7: ='Budget mensuel'!E11 -> 1 | F7: ='Budget mensuel'!F11 -> 1 | G7: ='Budget mensuel'!G11 -> 1 | H7: ='Budget mensuel'!H11 -> 2 | I7: ='Budget mensuel'!I11 -> 2 | J7: ='Budget mensuel'!J11 -> 2 | ... N7: ='Budget mensuel'!N11 -> 3
A8: Réel | B8: =SUM(C8:N8) -> 0
A9: Écart (réel − prévu) | B9: =SUM(C9:N9) -> 0 | C9: =IF(C8="",0,C8-C7) -> 0 | D9: =IF(D8="",0,D8-D7) -> 0 | E9: =IF(E8="",0,E8-E7) -> 0 | F9: =IF(F8="",0,F8-F7) -> 0 | G9: =IF(G8="",0,G8-G7) -> 0 | H9: =IF(H8="",0,H8-H7) -> 0 | I9: =IF(I8="",0,I8-I7) -> 0 | J9: =IF(J8="",0,J8-J7) -> 0 | ... N9: =IF(N8="",0,N8-N7) -> 0
A11: Chiffre d'affaires
A12: Prévu | B12: =SUM(C12:N12) -> 121955.36 | C12: ='Budget mensuel'!C13 -> 0 | D12: ='Budget mensuel'!D13 -> 0 | E12: ='Budget mensuel'!E13 -> 4919.6429 | F12: ='Budget mensuel'!F13 -> 9857.1429 | G12: ='Budget mensuel'!G13 -> 7125 | H12: ='Budget mensuel'!H13 -> 12955.357 | I12: ='Budget mensuel'!I13 -> 17892.857 | J12: ='Budget mensuel'!J13 -> 15160.714 | ... N12: ='Budget mensuel'!N13 -> 23196.429
A13: Réel | B13: =SUM(C13:N13) -> 0
A14: Écart (réel − prévu) | B14: =SUM(C14:N14) -> 0 | C14: =IF(C13="",0,C13-C12) -> 0 | D14: =IF(D13="",0,D13-D12) -> 0 | E14: =IF(E13="",0,E13-E12) -> 0 | F14: =IF(F13="",0,F13-F12) -> 0 | G14: =IF(G13="",0,G13-G12) -> 0 | H14: =IF(H13="",0,H13-H12) -> 0 | I14: =IF(I13="",0,I13-I12) -> 0 | J14: =IF(J13="",0,J13-J12) -> 0 | ... N14: =IF(N13="",0,N13-N12) -> 0
A16: Total des charges fixes
A17: Prévu | B17: =SUM(C17:N17) -> 12672 | C17: ='Budget mensuel'!C26 -> 2362 | D17: ='Budget mensuel'!D26 -> 1810 | E17: ='Budget mensuel'!E26 -> 1810 | F17: ='Budget mensuel'!F26 -> 1810 | G17: ='Budget mensuel'!G26 -> 610 | H17: ='Budget mensuel'!H26 -> 610 | I17: ='Budget mensuel'!I26 -> 610 | J17: ='Budget mensuel'!J26 -> 610 | ... N17: ='Budget mensuel'!N26 -> 610
A18: Réel | B18: =SUM(C18:N18) -> 0
A19: Écart (réel − prévu) | B19: =SUM(C19:N19) -> 0 | C19: =IF(C18="",0,C18-C17) -> 0 | D19: =IF(D18="",0,D18-D17) -> 0 | E19: =IF(E18="",0,E18-E17) -> 0 | F19: =IF(F18="",0,F18-F17) -> 0 | G19: =IF(G18="",0,G18-G17) -> 0 | H19: =IF(H18="",0,H18-H17) -> 0 | I19: =IF(I18="",0,I18-I17) -> 0 | J19: =IF(J18="",0,J18-J17) -> 0 | ... N19: =IF(N18="",0,N18-N17) -> 0
A21: Résultat d'exploitation
A22: Prévu | B22: =SUM(C22:N22) -> -16255.821 | C22: ='Budget mensuel'!C28 -> -2362 | D22: ='Budget mensuel'!D28 -> -1810 | E22: ='Budget mensuel'!E28 -> -2664.0714 | F22: ='Budget mensuel'!F28 -> -4162.2857 | G22: ='Budget mensuel'!G28 -> -1473.25 | H22: ='Budget mensuel'!H28 -> -231.92857 | I22: ='Budget mensuel'!I28 -> -1730.1429 | J22: ='Budget mensuel'!J28 -> -241.10714 | ... N22: ='Budget mensuel'!N28 -> 991.03571
A23: Réel | B23: =SUM(C23:N23) -> 0
A24: Écart (réel − prévu) | B24: =SUM(C24:N24) -> 0 | C24: =IF(C23="",0,C23-C22) -> 0 | D24: =IF(D23="",0,D23-D22) -> 0 | E24: =IF(E23="",0,E23-E22) -> 0 | F24: =IF(F23="",0,F23-F22) -> 0 | G24: =IF(G23="",0,G23-G22) -> 0 | H24: =IF(H23="",0,H23-H22) -> 0 | I24: =IF(I23="",0,I23-I22) -> 0 | J24: =IF(J23="",0,J23-J22) -> 0 | ... N24: =IF(N23="",0,N23-N22) -> 0
A26: Pièces du réel
A27: Pièce justifiant le réel (comptabilité, relevé, factures)

Sheet Plan financier 3 ans
A1: Plan financier sur 3 ans (simplifié)
A2: Prix et coûts par soirée constants (onglet Prix et marges). Ni TVA, ni impôt, ni délais de paiement.
A5: Poste | B5: Unité | C5: Année 1 | D5: Année 2 | E5: Année 3 | F5: Nature | G5: Source
A6: Activité
A7: Premier soir | B7: soirées par an | C7: ='Budget mensuel'!$B$7 -> 3 | D7: 8 | E7: 12 | F7: H | G7: Année 1 : budget mensuel. H : 2 soirées A par mois en année 2, 3 en année 3 ; privatisations et contrats cadres de 2 à 4 soirées par an et par client (5 PRODUIT, offre ; 3 MARKETING, personas)
A8: Le Voyage | B8: soirées par an | C8: ='Budget mensuel'!$B$8 -> 3 | D8: 8 | E8: 12 | F8: H | G8: Année 1 : budget mensuel. H : 2 soirées A par mois en année 2, 3 en année 3 ; privatisations et contrats cadres de 2 à 4 soirées par an et par client (5 PRODUIT, offre ; 3 MARKETING, personas)
A9: La Grande Nuit | B9: soirées par an | C9: ='Budget mensuel'!$B$9 -> 3 | D9: 8 | E9: 12 | F9: H | G9: Année 1 : budget mensuel. H : 2 soirées A par mois en année 2, 3 en année 3 ; privatisations et contrats cadres de 2 à 4 soirées par an et par client (5 PRODUIT, offre ; 3 MARKETING, personas)
A10: Privatisations | B10: soirées par an | C10: ='Budget mensuel'!$B$10 -> 7 | D10: 24 | E10: 48 | F10: H | G10: Année 1 : budget mensuel. H : 2 soirées A par mois en année 2, 3 en année 3 ; privatisations et contrats cadres de 2 à 4 soirées par an et par client (5 PRODUIT, offre ; 3 MARKETING, personas)
A11: Nombre total de soirées | B11: soirées par an | C11: =SUM(C7:C10) -> 16 | D11: =SUM(D7:D10) -> 48 | E11: =SUM(E7:E10) -> 84
A12: Compte de résultat simplifié
A13: Chiffre d'affaires | B13: € HT | C13: =C7*'Prix et marges'!$C$17+C8*'Prix et marges'!$D$17+C9*'Prix et marges'!$E$17+C10*'Prix et marges'!$F$17 -> 121955.36 | D13: =D7*'Prix et marges'!$C$17+D8*'Prix et marges'!$D$17+D9*'Prix et marges'!$E$17+D10*'Prix et marges'!$F$17 -> 368071.43 | E13: =E7*'Prix et marges'!$C$17+E8*'Prix et marges'!$D$17+E9*'Prix et marges'!$E$17+E10*'Prix et marges'!$F$17 -> 648535.71
A14: Coûts directs | B14: € HT | C14: =C7*'Prix et marges'!$C$34+C8*'Prix et marges'!$D$34+C9*'Prix et marges'!$E$34+C10*'Prix et marges'!$F$34 -> 125539.18 | D14: =D7*'Prix et marges'!$C$34+D8*'Prix et marges'!$D$34+D9*'Prix et marges'!$E$34+D10*'Prix et marges'!$F$34 -> 371056.86 | E14: =E7*'Prix et marges'!$C$34+E8*'Prix et marges'!$D$34+E9*'Prix et marges'!$E$34+E10*'Prix et marges'!$F$34 -> 638228.14
A15: Marge sur coûts directs | B15: € HT | C15: =C13-C14 -> -3583.8214 | D15: =D13-D14 -> -2985.4286 | E15: =E13-E14 -> 10307.571
A16: Taux de marge | B16: % du CA | C16: =IF(C13>0,C15/C13,0) -> -0.029386339 | D16: =IF(D13>0,D15/D13,0) -> -0.0081110033 | E16: =IF(E13>0,E15/E13,0) -> 0.015893606
A17: Charges fixes | B17: € HT par an | C17: ='Budget mensuel'!$B$26 -> 12672 | D17: 60000 | E17: 150000 | F17: H | G17: Année 1 : budget mensuel. H année 2 : un coordinateur au SMIC (F 1 867,02 € brut par mois au 01/06/2026, Éditions Tissot), marketing et honoraires. H année 3 : deux fondateurs rémunérés et un commercial
A18: Résultat d'exploitation | B18: € HT | C18: =C15-C17 -> -16255.821 | D18: =D15-D17 -> -62985.429 | E18: =E15-E17 -> -139692.43
A19: Besoin de financement
A20: Investissements (site, identité, coffrets, matériel) | B20: € HT | C20: 3000 | D20: 5000 | E20: 10000 | F20: H | G20: H : site et identité visuelle, coffrets cadeaux numérotés, petit matériel de service
A21: Flux de l'année (résultat − investissements) | B21: € | C21: =C18-C20 -> -19255.821 | D21: =D18-D20 -> -67985.429 | E21: =E18-E20 -> -149692.43
A22: Flux cumulé | B22: € | C22: =C21 -> -19255.821 | D22: =C22+D21 -> -87241.25 | E22: =D22+E21 -> -236933.68
A23: Seuil de rentabilité | B23: soirées par an | C23: =IF(C11>0,IF(C15>0,C17/(C15/C11),0),0) -> 0 | D23: =IF(D11>0,IF(D15>0,D17/(D15/D11),0),0) -> 0 | E23: =IF(E11>0,IF(E15>0,E17/(E15/E11),0),0) -> 1222.4024
A25: Besoin de financement (point bas du flux cumulé) | B25: € | C25: =MAX(0,-MIN(C22:E22)) -> 236933.68
A27: Année 1 : nombre de soirées et charges fixes repris du budget mensuel (texte vert). Années 2 et 3 : hypothèses temporaires. Le financement se suit dans 2 FINANCE/FINANCEMENT.
