Workbook

Sheet Mode d'emploi
A1: Modèle Pop Tables - budget sur 36 mois, plan financier, prix et marges
A2: Pop Tables · Pôle Finance · Version du 28/10/2026 (soir), selon les décisions D-02 à D-20, revue par le responsable Finance. Remplace le modèle du 27/10 (rangé dans 2 FINANCE/OLD).
A4: Rubrique | B4: Contenu
A5: Objet | B5: Budget, plan financier, prix et marges (2 FINANCE/PREVISIONS/LISEZ-MOI.md).
A6: État du fichier | B6: Revu le 28/10/2026 (soir) par le responsable Finance : nouvelles villes actives dès novembre ; 40 privatisations par ville et par an dès l'année 2 ; coordinateurs (1 par événement hebdomadaire) et commerciaux (1 par ville active, dès l'année 3) calculés à partir de l'activité ; un manager en année 3 ; locaux et logiciels par poste payé ; prix et coûts revus dans « Prix et marges ». Décisions D-05, D-06, D-08, D-14, D-15, D-19 intégrées ; campagne de lancement (10 000 €), protection juridique et assurance (2 % du CA) et budget des ventes. Toutes les autres valeurs restent des hypothèses (H) : voir la fiche des données manquantes du 28/10/2026.
A7: Onglets | B7: « Prix et marges » : l'économie d'une soirée par offre. « Staffing » : effectifs des Opérations (sert au surcoût des pilotes). « Budget 36 mois » : activité par ville, chiffre d'affaires, coûts, frais généraux détaillés, investissements, TVA et trésorerie avant levée, mois par mois de novembre 2026 à octobre 2029. « TVA » : taux et règles. « Prévu et réel » : suivi de l'année 1. « Plan financier 3 ans » : totaux annuels et besoin de financement. « Ressources humaines » : postes, salaires et premiers mois payés.
A8: Offres modélisées | B8: Les trois soirées de l'offre A (Premier soir, Le Voyage, La Grande Nuit) et la privatisation de l'offre B avec un chef confirmé pour 10 convives, d'après 5 PRODUIT (offre, pricing, pilotes). Les prix y sont des propositions (P), non validées par l'équipe.
A9: Prévision et résultat | B9: Une prévision n'est pas un résultat : la comparer au réel dès qu'il est connu (onglet « Prévu et réel »), en citant la pièce du réel. Un objectif de chiffre d'affaires n'est pas une facture.
A10: Simplifications | B10: Prix affichés TTC convertis en HT avec un taux de TVA moyen (H). Ni impôt sur les sociétés, ni délais de paiement. Les acomptes et remboursements (seuil de 70 % à J-14) ne sont pas modélisés.
A11: Légende des cellules | B11: Cellule jaune, texte bleu : donnée à saisir. Cellule grise : formule, ne pas modifier. Texte vert : valeur reprise d'un autre onglet. Ligne verte « Exemple » : montre le format attendu, à remplacer ou supprimer.
A12: Colonne « Nature » | B12: F = fait constaté dans une pièce citée · I = inférence · P = proposition · H = hypothèse à valider (voir RULES.md). Si la pièce ne dit pas le chiffre : « non établi par les sources ».
A13: Colonne « Source » | B13: La pièce et l'endroit exact (ex. : S04, § Contexte, ou le nom de la note du dépôt). Signaler un chiffre tiré d'un argumentaire (plan d'affaires, présentation) plutôt que d'un document de gestion (facture, relevé, procès-verbal).
A14: Unités | B14: Montants en euros hors taxes, sauf mention contraire. Pourcentages saisis en % (ex. : 15 %).
A15: Cadre du projet | B15: Pop Tables : soirées gastronomiques éphémères sur le segment du luxe, un chef rare dans un restaurant d'exception pendant sa fermeture. Places à l'unité en pré-vente (drops) et privatisations de salle. Source : 1 DIRECTION/STRATEGIE/2026 1028 Pop Tables - Cadre de référence (D-02 à D-19).
... A20: TVA et CFE | B20: Mis à jour le 28/10/2026 : onglet « TVA » (taux par poste en hypothèse, TVA collectée, déductible et reversée chaque mois, crédit reporté) ; son effet sur la trésorerie (ligne 51) est repris dans 2 FINANCE/TRESORERIE. CFE ajoutée aux frais généraux des années 2 et 3 (onglet Frais généraux 3 ans, ligne 24). Le compte de résultat reste hors taxes ; pas d'impôt sur les sociétés (pertes).

Sheet Prix et marges
A1: Prix et marges d'une soirée
A2: Une offre par colonne. Lignes grises calculées. Montants HT sauf mention TTC.
A3: Valeurs du 27/10/2026 : prix et capacités proposés par le Produit (P) ; coûts en hypothèses temporaires (H), à remplacer par des devis.
A5: Poste | B5: Unité | C5: Premier soir (offre A) | D5: Le Voyage (offre A) | E5: La Grande Nuit (offre A) | F5: Privatisation, chef confirmé (offre B) | G5: Nature | H5: Source | I5: Fourni par
A6: 1. Recettes
A7: Capacité | B7: couverts | C7: 40 | D7: 35 | E7: 30 | F7: 30 | G7: F | H7: Décision D-05 de la Direction du 28/10/2026 (« Jauge — validé suivant fichier finance ») : 40 / 35 / 30 / 20 couverts. Relevé de décisions du 28/10 (soir) | I7: Direction
A8: Taux de remplissage | B8: % des couverts | C8: 1 | D8: 1 | E8: 1 | F8: 1 | G8: H | H8: H du responsable Finance (28/10/2026) : salle pleine. D-05 porte sur la jauge, pas sur le remplissage ; seuil de confirmation à J-14 à revoir par le Produit (relevé de décisions, § 3) | I8: Finance
A9: Convives payants | B9: personnes | C9: =ROUND(C7*C8,0) -> 40 | D9: =ROUND(D7*D8,0) -> 35 | E9: =ROUND(E7*E8,0) -> 30 | F9: =ROUND(F7*F8,0) -> 30
A10: Prix affiché TTC par convive | B10: € TTC par personne | C10: 290 | D10: 420 | E10: 690 | F10: 500 | G10: P | H10: 5 PRODUIT/Fou d'un soir le pricing.md (@Fréd, 27/10/2026), prix des soirées et grille de privatisation (prix TTC tout compris) | I10: Produit
A11: Forfait affiché TTC par soirée (privatisation) | B11: € TTC | C11: 0 | D11: 0 | E11: 0 | G11: P | H11: 5 PRODUIT/Fou d'un soir le pricing.md (@Fréd, 27/10/2026), forfait de privatisation chef confirmé ; H : forfait supposé TTC comme les prix de l'offre A | I11: Produit
A12: Taux de TVA moyen | B12: % | C12: 0.12 | D12: 0.12 | E12: 0.12 | F12: 0.12 | G12: H | H12: Taux mixte (le pricing le signale « à vérifier avec la finance ») : 10 % sur la restauration, 20 % sur les boissons alcoolisées (règle fiscale à confirmer par un expert-comptable) ; H : boissons alcoolisées environ 20 % du prix | I12: Finance
A13: Prix HT par convive | B13: € HT par personne | C13: =C10/(1+C12) -> 258.92857 | D13: =D10/(1+D12) -> 375 | E13: =E10/(1+E12) -> 616.07143 | F13: =F10/(1+F12) -> 446.42857
A14: Forfait HT | B14: € HT | C14: =C11/(1+C12) -> 0 | D14: =D11/(1+D12) -> 0 | E14: =E11/(1+E12) -> 0 | F14: =F11/(1+F12) -> 0
A15: Minimum facturé (0 si aucun) | B15: € HT | C15: 0 | D15: 0 | E15: 0 | F15: 0 | G15: H | H15: Aucun minimum prévu par le Produit | I15: Produit
A16: Revenus complémentaires (partenariats, options) | B16: € HT | C16: 0 | D16: 0 | E16: 0 | F16: 0 | G16: H | H16: Non établi par les sources : partenariats vins et champagne envisagés, aucun accord | I16: Ventes
A17: Chiffre d'affaires de la soirée | B17: € HT | C17: =MAX(C9*C13+C14,C15)+C16 -> 10357.143 | D17: =MAX(D9*D13+D14,D15)+D16 -> 13125 | E17: =MAX(E9*E13+E14,E15)+E16 -> 18482.143 | F17: =MAX(F9*F13+F14,F15)+F16 -> 13392.857
A18: 2. Coûts directs de la soirée
A19: Mise à disposition du lieu (restaurateur) | B19: € HT | C19: 1000 | D19: 1000 | E19: 1000 | F19: 1000 | G19: H | H19: F location de restaurants à Paris de 35 à 620 €/h, moyenne environ 373 à 386 €/h (Giggster) ; privatisation « à partir de 2 916 € » (Privateaser), cités dans 3 MARKETING/old project/MARCHE. La cible du Produit (11 à 12 % du prix HT) donnerait 750 à 1 350 € : écart signalé | I19: Ventes
A20: Chef : cachet et déplacement (part fixe) | B20: € HT | C20: 950 | D20: 2000 | E20: 3500 | F20: 1800 | G20: H | H20: Calé sur la répartition cible du Produit (chef 15 / 22 / 30 % du prix HT, P, 5 PRODUIT/Fou d'un soir le pricing.md (@Fréd, 27/10/2026)) ; F chef privé 500 à 1 400 € par jour hors matières (Chefs Talents 2026, cité dans 3 MARKETING/new project/3 Concurrence) | I20: Ventes
A21: Chef : part du chiffre d'affaires | B21: % du CA | C21: 0 | D21: 0 | E21: 0 | F21: 0 | G21: H | H21: Rémunération du chef supposée entièrement fixe ; une part variable reste possible (descriptif du projet 3, § 6) | I21: Ventes
A22: Rémunération du chef | B22: € HT | C22: =C20+C21*C17 -> 950 | D22: =D20+D21*D17 -> 2000 | E22: =E20+E21*E17 -> 3500 | F22: =F20+F21*F17 -> 1800
A23: Matières premières par convive | B23: € HT par personne | C23: 55 | D23: 70 | E23: 90 | F23: 70 | G23: H | H23: Calé sur la cible du Produit (matières et vins 33 / 30 / 27 % du prix HT, P) ; F ratio matières et boissons idéalement sous 35 % (Keobiz, cité dans le descriptif du projet 3) | I23: Opérations
A24: Vins ou jus d'accord par convive | B24: € HT par personne | C24: 30 | D24: 42 | E24: 60 | F24: 30 | G24: H | H24: Même source ; accord mets-jus au même coût que l'accord mets-vins (pricing : « coût réel reste à chiffrer ») | I24: Opérations
A25: Matières et boissons | B25: € HT | C25: =C9*(C23+C24) -> 3400 | D25: =D9*(D23+D24) -> 3920 | E25: =E9*(E23+E24) -> 4500 | F25: =F9*(F23+F24) -> 3000
A26: Équipe de service, brigade, sommelier et plonge | B26: € HT | C26: =0.15*C17 -> 1553.5714 | D26: =0.2*D17 -> 2625 | E26: =0.2*E17 -> 3696.4286 | F26: =0.15*F17 -> 2008.9286 | G26: F | H26: Décision D-06 (28/10/2026) : enveloppe de 15 % du CA HT (Premier soir, privatisation) ou 20 % (Le Voyage, La Grande Nuit) ; les Opérations ajustent le staffing. Proposition des Opérations du 28/10 (branche non fusionnée) : 2 516 / 2 516 / 2 201 / 1 935 €, non reprise | I26: Direction
A27: Ménage et remise en état du lieu | B27: € HT | C27: 150 | D27: 150 | E27: 150 | F27: 150 | G27: H | H27: Hypothèse temporaire ; cible « frais » du Produit 8 / 6 / 5 % du prix HT | I27: Opérations
A28: Assurance de la soirée | B28: € HT | C28: 150 | D28: 150 | E28: 150 | F28: 150 | G28: H | H28: Hypothèse temporaire, devis d'assureur à obtenir | I28: Juridique
A29: Décor, souvenir numéroté, petit matériel | B29: € HT | C29: 200 | D29: 200 | E29: 200 | F29: 150 | G29: H | H29: Hypothèse temporaire (menu numéroté, souvenir, mise en scène) | I29: Opérations
A30: Frais de paiement | B30: % du CA | C30: 0.016 | D30: 0.016 | E30: 0.016 | F30: 0 | G30: H | H30: F Stripe 1,5 % + 0,25 € par carte européenne (stripe.com/fr/pricing, consulté le 27/10/2026), arrondi à 1,6 % ; privatisation réglée par virement (H) | I30: Finance
A31: Commission d'apporteur (concierge, agence) | B31: % du CA | C31: 0 | D31: 0.05 | E31: 0.05 | F31: 0.05 | G31: H | H31: F honoraires d'agence 10 à 20 % du budget (BlackTrombone 2026, cité dans le descriptif du projet 3) ; part des ventes via les concierges à mesurer pendant les pilotes | I31: Marketing
A32: Frais et commissions | B32: € HT | C32: =(C30+C31)*C17 -> 165.71429 | D32: =(D30+D31)*D17 -> 866.25 | E32: =(E30+E31)*E17 -> 1219.8214 | F32: =(F30+F31)*F17 -> 669.64286
A33: Autres coûts directs (photographe supprimé, D-08) | B33: € HT | C33: 0 | D33: 0 | E33: 0 | F33: 0 | G33: F | H33: Décision D-08 (28/10/2026) : suppression du photographe | I33: Direction
A34: Total des coûts directs | B34: € HT | C34: =C19+C22+C25+C26+C27+C28+C29+C32+C33 -> 7569.2857 | D34: =D19+D22+D25+D26+D27+D28+D29+D32+D33 -> 10911.25 | E34: =E19+E22+E25+E26+E27+E28+E29+E32+E33 -> 14416.25 | F34: =F19+F22+F25+F26+F27+F28+F29+F32+F33 -> 8928.5714
A35: 3. Marge, partage de la valeur et seuils
A36: Marge sur coûts directs | B36: € HT | C36: =C17-C34 -> 2787.8571 | D36: =D17-D34 -> 2213.75 | E36: =E17-E34 -> 4065.8929 | F36: =F17-F34 -> 4464.2857
A37: Taux de marge | B37: % du CA | C37: =IF(C17>0,C36/C17,0) -> 0.26917241 | D37: =IF(D17>0,D36/D17,0) -> 0.16866667 | E37: =IF(E17>0,E36/E17,0) -> 0.21999034 | F37: =IF(F17>0,F36/F17,0) -> 0.33333333
A38: Marge par convive payant | B38: € HT par personne | C38: =IF(C9>0,C36/C9,0) -> 69.696429 | D38: =IF(D9>0,D36/D9,0) -> 63.25 | E38: =IF(E9>0,E36/E9,0) -> 135.52976 | F38: =IF(F9>0,F36/F9,0) -> 148.80952
A39: Part du lieu | B39: % du CA | C39: =IF(C17>0,C19/C17,0) -> 0.096551724 | D39: =IF(D17>0,D19/D17,0) -> 0.076190476 | E39: =IF(E17>0,E19/E17,0) -> 0.05410628 | F39: =IF(F17>0,F19/F17,0) -> 0.074666667
A40: Part du chef | B40: % du CA | C40: =IF(C17>0,C22/C17,0) -> 0.091724138 | D40: =IF(D17>0,D22/D17,0) -> 0.15238095 | E40: =IF(E17>0,E22/E17,0) -> 0.18937198 | F40: =IF(F17>0,F22/F17,0) -> 0.1344
A41: Part de la société (marge) | B41: % du CA | C41: =C37 -> 0.26917241 | D41: =D37 -> 0.16866667 | E41: =E37 -> 0.21999034 | F41: =F37 -> 0.33333333
...

Sheet Staffing
A1: Staffing d'une soirée : scénario S0 (pilotes) et scénario S3 (soirées récurrentes)
A2: Effectifs repris des Opérations (propositions). Heures et coûts horaires : hypothèses temporaires (H), aucun devis à ce jour.
A4: Personnel de la soirée (salle, sommellerie, brigade, plonge) : toujours fourni et payé par Fou d'un soir. | H4: P | I4: Orientation du responsable Opérations du 28/10/2026, à porter au registre des décisions par la Direction (6 OPERATIONS/PRODUCTION/2026 1028 Scénarios de staffing - leviers de coût.md, § 3). Remplace l'option « salle fournie par le restaurant ».
A6: Rôle (scénario S0 : équipe complète, criticité C2) | B6: Heures par personne | C6: Coût horaire chargé (€) | D6: Premier soir | E6: Le Voyage | F6: La Grande Nuit | G6: Privatisation (table de 10) | H6: Poste de salle (1 = oui) | I6: Source et nature
A7: Brigade (second, commis) | B7: 9 | C7: 35 | D7: 3 | E7: 3 | F7: 2 | G7: 1 | H7: 0 | I7: Effectifs P (Opérations). H : 9 h (mise en place et service) à 35 €/h, coût d'un extra retenu dans le descriptif du projet 3 (H), à confirmer par devis
A8: Maître d'hôtel | B8: 8 | C8: 45 | D8: 1 | E8: 1 | F8: 1 | G8: 1 | H8: 1 | I8: Effectifs P (Opérations). H : 8 h à 45 €/h
A9: Serveurs (base) | B9: 7 | C9: 35 | D9: 4 | E9: 4 | F9: 3 | G9: 2 | H9: 1 | I9: Effectifs P (Opérations : 1 serveur pour 7 couverts). H : 7 h à 35 €/h
A10: Serveur de réserve | B10: 7 | C10: 35 | D10: 1 | E10: 1 | F10: 1 | G10: 1 | H10: 1 | I10: Effectifs P (Opérations : 1 en criticité C2 et C3). H : 7 h à 35 €/h
A11: Sommelier invité | B11: 7 | C11: 60 | D11: 1 | E11: 1 | F11: 1 | G11: 1 | H11: 0 | I11: Effectifs P (Opérations). H : 7 h à 60 €/h, cachet à négocier
A12: Aide sommelier | B12: 7 | C12: 38 | D12: 1 | E12: 1 | F12: 1 | G12: 0 | H12: 0 | I12: Effectifs P (Opérations : à partir de 20 couverts). H : 7 h à 38 €/h
A13: Plongeurs | B13: 7 | C13: 30 | D13: 2 | E13: 2 | F13: 2 | G13: 1 | H13: 0 | I13: Effectifs P (Opérations). H : 7 h à 30 €/h
A14: Responsable de production (nous) | B14: 10 | C14: 0 | D14: 1 | E14: 1 | F14: 1 | G14: 1 | H14: 0 | I14: Effectifs P (Opérations). H : assuré par un fondateur, non rémunéré la première année (coût dans les frais généraux)
A15: Interlocuteur client (Ventes) | B15: 5 | C15: 0 | D15: 1 | E15: 1 | F15: 1 | G15: 1 | H15: 0 | I15: Effectifs P (Opérations : en C2 et C3). H : assuré par un fondateur, non rémunéré la première année
A16: Chef invité : 1 par soirée, compté à part (cachet, Prix et marges ligne 20)
A18: Personnes mobilisées, hors chef | D18: =SUM(D7:D15) -> 15 | E18: =SUM(E7:E15) -> 15 | F18: =SUM(F7:F15) -> 13 | G18: =SUM(G7:G15) -> 9
A19: dont postes de salle | D19: =SUMPRODUCT(D7:D15,$H$7:$H$15) -> 6 | E19: =SUMPRODUCT(E7:E15,$H$7:$H$15) -> 6 | F19: =SUMPRODUCT(F7:F15,$H$7:$H$15) -> 5 | G19: =SUMPRODUCT(G7:G15,$H$7:$H$15) -> 4
A20: Heures de travail payées | D20: =SUMPRODUCT(D7:D15,$B$7:$B$15,--($C$7:$C$15>0)) -> 98 | E20: =SUMPRODUCT(E7:E15,$B$7:$B$15,--($C$7:$C$15>0)) -> 98 | F20: =SUMPRODUCT(F7:F15,$B$7:$B$15,--($C$7:$C$15>0)) -> 82 | G20: =SUMPRODUCT(G7:G15,$B$7:$B$15,--($C$7:$C$15>0)) -> 52
A21: Coût de l'équipe S0, pilotes (€ HT) | D21: =SUMPRODUCT(D7:D15,$B$7:$B$15,$C$7:$C$15) -> 3636 | E21: =SUMPRODUCT(E7:E15,$B$7:$B$15,$C$7:$C$15) -> 3636 | F21: =SUMPRODUCT(F7:F15,$B$7:$B$15,$C$7:$C$15) -> 3076 | G21: =SUMPRODUCT(G7:G15,$B$7:$B$15,$C$7:$C$15) -> 2040
A23: Source S0 : 6 OPERATIONS/PRODUCTION/2026 1028 Calculateur de staffing par événement.xlsx (Opérations, 28/10/2026). Source S3 : 6 OPERATIONS/PRODUCTION/2026 1028 Scénarios de staffing - leviers de coût.md (§ 4 et 5).
A25: Rôle (scénario S3 : soirées récurrentes optimisées) | B25: Heures par personne | C25: Coût horaire chargé (€) | D25: Premier soir | E25: Le Voyage | F25: La Grande Nuit | G25: Privatisation (table de 10) | H25: Poste de salle (1 = oui) | I25: Source et nature
A26: =A7 -> Brigade (second, commis) | B26: =B7 -> 9 | C26: =C7 -> 35 | D26: 3 | E26: 3 | F26: 2 | G26: 1 | H26: =H7 -> 0 | I26: P (Opérations) : inchangé
A27: =A8 -> Maître d'hôtel | B27: =B8 -> 8 | C27: =C8 -> 45 | D27: 1 | E27: 1 | F27: 1 | G27: 1 | H27: =H8 -> 1 | I27: P (Opérations) : inchangé
A28: =A9 -> Serveurs (base) | B28: =B9 -> 7 | C28: =C9 -> 35 | D28: 3 | E28: 3 | F28: 3 | G28: 2 | H28: =H9 -> 1 | I28: P (Opérations), levier L2 : 1 serveur pour 9 couverts (24 couverts : 3 au lieu de 4 ; 20 couverts : 3, inchangé)
A29: =A10 -> Serveur de réserve | B29: =B10 -> 7 | C29: =C10 -> 35 | D29: 0 | E29: 0 | F29: 0 | G29: 1 | H29: =H10 -> 1 | I29: P (Opérations), levier L1 : soirée récurrente classée C1, pas de serveur de réserve. Privatisation : I (Finance), maintenue en C2, contrat client
A30: =A11 -> Sommelier invité | B30: =B11 -> 7 | C30: =C11 -> 60 | D30: 1 | E30: 1 | F30: 1 | G30: 1 | H30: =H11 -> 0 | I30: P (Opérations) : inchangé
A31: =A12 -> Aide sommelier | B31: =B12 -> 7 | C31: =C12 -> 38 | D31: 1 | E31: 1 | F31: 1 | G31: 0 | H31: =H12 -> 0 | I31: P (Opérations) : aide sommelier maintenu (levier L4 écarté, § 6.3)
A32: =A13 -> Plongeurs | B32: =B13 -> 7 | C32: =C13 -> 30 | D32: 1 | E32: 1 | F32: 1 | G32: 1 | H32: =H13 -> 0 | I32: P (Opérations), levier L3 : vaisselle sale reprise par le loueur, −1 plongeur (réponse d'Options attendue). Privatisation : I (Finance), 1 plongeur maintenu
A33: =A14 -> Responsable de production (nous) | B33: =B14 -> 10 | C33: =C14 -> 0 | D33: 1 | E33: 1 | F33: 1 | G33: 1 | H33: =H14 -> 0 | I33: P (Opérations) : fondateur, non rémunéré la première année
A34: =A15 -> Interlocuteur client (Ventes) | B34: =B15 -> 5 | C34: =C15 -> 0 | D34: 0 | E34: 0 | F34: 0 | G34: 1 | H34: =H15 -> 0 | I34: P (Opérations) : pas nécessaire en C1. Privatisation maintenue (contrat client). Coût nul
A36: Personnes mobilisées S3, hors chef | D36: =SUM(D26:D34) -> 11 | E36: =SUM(E26:E34) -> 11 | F36: =SUM(F26:F34) -> 10 | G36: =SUM(G26:G34) -> 9
A37: dont postes de salle | D37: =SUMPRODUCT(D26:D34,$H$26:$H$34) -> 4 | E37: =SUMPRODUCT(E26:E34,$H$26:$H$34) -> 4 | F37: =SUMPRODUCT(F26:F34,$H$26:$H$34) -> 4 | G37: =SUMPRODUCT(G26:G34,$H$26:$H$34) -> 4
A38: Heures de travail payées | D38: =SUMPRODUCT(D26:D34,$B$26:$B$34,--($C$26:$C$34>0)) -> 77 | E38: =SUMPRODUCT(E26:E34,$B$26:$B$34,--($C$26:$C$34>0)) -> 77 | F38: =SUMPRODUCT(F26:F34,$B$26:$B$34,--($C$26:$C$34>0)) -> 68 | G38: =SUMPRODUCT(G26:G34,$B$26:$B$34,--($C$26:$C$34>0)) -> 52
A39: Coût de l'équipe S3, soirées récurrentes (€ HT) | D39: =SUMPRODUCT(D26:D34,$B$26:$B$34,$C$26:$C$34) -> 2936 | E39: =SUMPRODUCT(E26:E34,$B$26:$B$34,$C$26:$C$34) -> 2936 | F39: =SUMPRODUCT(F26:F34,$B$26:$B$34,$C$26:$C$34) -> 2621 | G39: =SUMPRODUCT(G26:G34,$B$26:$B$34,$C$26:$C$34) -> 2040
A40: Surcoût d'une soirée pilote (S0 − S3) | D40: =D21-D39 -> 700 | E40: =E21-E39 -> 700 | F40: =F21-F39 -> 455 | G40: =G21-G39 -> 0
A42: Le coût de référence d'une soirée (Prix et marges, ligne 26) est celui de S3. Les deux pilotes (Premier soir et La Grande Nuit) gardent l'équipe complète S0 : leur surcoût (ligne 40) est ajouté au budget comme un coût de test (Budget mensuel, lignes 37 à 40).
A43: Non chiffré : le levier L3 rend la location de vaisselle un peu plus chère (montant attendu du loueur Options).

Sheet Budget 36 mois
A1: Budget détaillé sur 36 mois (novembre 2026 - octobre 2029)
A2: Pop Tables · Pôle Finance · Version du 28/10/2026 (soir), selon les décisions D-02 à D-19 de la Direction. Une colonne par mois ; recettes et coûts directs repris de « Prix et marges » ; ressources humaines reprises de « Ressources humaines ». Montants HT, sauf TVA et trésorerie.
A3: Premier mois : | B3: 46327
D4: Mois n° | E4: 1 | F4: 2 | G4: 3 | H4: 4 | I4: 5 | J4: 6 | K4: 7 | L4: 8 | M4: 9 | N4: 10 | O4: 11 | P4: 12 | Q4: 13 | R4: 14 | S4: 15 | T4: 16 | U4: 17 | V4: 18 | W4: 19 | X4: 20 | Y4: 21 | Z4: 22 | AA4: 23 | AB4: 24 | AC4: 25 | AD4: 26 | AE4: 27 | AF4: 28 | AG4: 29 | AH4: 30 | AI4: 31 | AJ4: 32 | AK4: 33 | AL4: 34 | AM4: 35 | AN4: 36
A5: Poste | B5: Année 1 (nov. 2026 - oct. 2027) | C5: Année 2 (nov. 2027 - oct. 2028) | D5: Année 3 (nov. 2028 - oct. 2029) | E5: =EDATE($B$3,E$4-1) -> 46327 | F5: =EDATE($B$3,F$4-1) -> 46357 | G5: =EDATE($B$3,G$4-1) -> 46388 | H5: =EDATE($B$3,H$4-1) -> 46419 | I5: =EDATE($B$3,I$4-1) -> 46447 | J5: =EDATE($B$3,J$4-1) -> 46478 | K5: =EDATE($B$3,K$4-1) -> 46508 | L5: =EDATE($B$3,L$4-1) -> 46539 | ... AN5: =EDATE($B$3,AN$4-1) -> 47392 | AO5: Nature | AP5: Source et explication | AQ5: Taux de TVA déductible
A6: 1. Villes et activité (nombre de soirées)
A7: Villes actives | B7: =P7 -> 1 | C7: =AB7 -> 3 | D7: =AN7 -> 6 | E7: 1 | F7: 1 | G7: 1 | H7: 1 | I7: 1 | J7: 1 | K7: 1 | L7: 1 | M7: 1 | N7: 1 | O7: 1 | P7: 1 | Q7: 3 | R7: 3 | S7: 3 | T7: 3 | U7: 3 | V7: 3 | W7: 3 | X7: 3 | Y7: 3 | Z7: 3 | AA7: 3 | AB7: 3 | AC7: 6 | AD7: 6 | AE7: 6 | AF7: 6 | AG7: 6 | AH7: 6 | AI7: 6 | AJ7: 6 | AK7: 6 | AL7: 6 | AM7: 6 | AN7: 6 | AO7: F / H | AP7: Décision D-15 : Paris en année 1 ; + 1 ville en France et + 1 à l'étranger en année 2 ; + 1 en France et + 2 à l'étranger en année 3. Les nouvelles villes sont actives dès le début de l'année (novembre) ; villes non nommées
A8: Premier soir (place à l'unité) | B8: =SUM(E8:P8) -> 3 | C8: =SUM(Q8:AB8) -> 11 | D8: =SUM(AC8:AN8) -> 22 | E8: 0 | F8: 0 | G8: 1 | H8: 0 | I8: 0 | J8: 1 | K8: 0 | L8: 0 | M8: 1 | N8: 0 | O8: 0 | P8: 0 | Q8: 1 | R8: 1 | S8: 1 | T8: 1 | U8: 1 | V8: 1 | W8: 1 | X8: 1 | Y8: 1 | Z8: 0 | AA8: 1 | AB8: 1 | AC8: 2 | AD8: 2 | AE8: 2 | AF8: 2 | AG8: 2 | AH8: 2 | AI8: 2 | AJ8: 2 | AK8: 2 | AL8: 0 | AM8: 2 | AN8: 2 | AO8: H | AP8: D-15 : 1 soirée « place à l'unité » par mois et par ville, pas de soirée en août (H). Les trois offres tournent dans chaque ville (H) : 1/1/1 par mois en année 2, 2/2/2 en année 3. Année 1 : calendrier du budget du 27/10, pilotes compris
A9: Le Voyage (place à l'unité) | B9: =SUM(E9:P9) -> 3 | C9: =SUM(Q9:AB9) -> 11 | D9: =SUM(AC9:AN9) -> 22 | E9: 0 | F9: 0 | G9: 0 | H9: 0 | I9: 1 | J9: 0 | K9: 0 | L9: 1 | M9: 0 | N9: 0 | O9: 0 | P9: 1 | Q9: 1 | R9: 1 | S9: 1 | T9: 1 | U9: 1 | V9: 1 | W9: 1 | X9: 1 | Y9: 1 | Z9: 0 | AA9: 1 | AB9: 1 | AC9: 2 | AD9: 2 | AE9: 2 | AF9: 2 | AG9: 2 | AH9: 2 | AI9: 2 | AJ9: 2 | AK9: 2 | AL9: 0 | AM9: 2 | AN9: 2 | AO9: H | AP9: Idem
A10: La Grande Nuit (place à l'unité) | B10: =SUM(E10:P10) -> 3 | C10: =SUM(Q10:AB10) -> 11 | D10: =SUM(AC10:AN10) -> 22 | E10: 0 | F10: 0 | G10: 0 | H10: 1 | I10: 0 | J10: 0 | K10: 1 | L10: 0 | M10: 0 | N10: 0 | O10: 1 | P10: 0 | Q10: 1 | R10: 1 | S10: 1 | T10: 1 | U10: 1 | V10: 1 | W10: 1 | X10: 1 | Y10: 1 | Z10: 0 | AA10: 1 | AB10: 1 | AC10: 2 | AD10: 2 | AE10: 2 | AF10: 2 | AG10: 2 | AH10: 2 | AI10: 2 | AJ10: 2 | AK10: 2 | AL10: 0 | AM10: 2 | AN10: 2 | AO10: H | AP10: Idem
A11: Soirées « place à l'unité » (B2C, pré-vente) | B11: =SUM(E11:P11) -> 9 | C11: =SUM(Q11:AB11) -> 33 | D11: =SUM(AC11:AN11) -> 66 | E11: =SUM(E8:E10) -> 0 | F11: =SUM(F8:F10) -> 0 | G11: =SUM(G8:G10) -> 1 | H11: =SUM(H8:H10) -> 1 | I11: =SUM(I8:I10) -> 1 | J11: =SUM(J8:J10) -> 1 | K11: =SUM(K8:K10) -> 1 | L11: =SUM(L8:L10) -> 1 | ... AN11: =SUM(AN8:AN10) -> 6
A12: Privatisations de salle (B2C et B2B, chef confirmé) | B12: =SUM(E12:P12) -> 7 | C12: =SUM(Q12:AB12) -> 120 | D12: =SUM(AC12:AN12) -> 240 | E12: 0 | F12: 0 | G12: 0 | H12: 0 | I12: 0 | J12: 1 | K12: 1 | L12: 1 | M12: 0 | N12: 0 | O12: 2 | P12: 2 | Q12: =Q$7*$B$90/12 -> 10 | R12: =R$7*$B$90/12 -> 10 | S12: =S$7*$B$90/12 -> 10 | T12: =T$7*$B$90/12 -> 10 | U12: =U$7*$B$90/12 -> 10 | V12: =V$7*$B$90/12 -> 10 | W12: =W$7*$B$90/12 -> 10 | X12: =X$7*$B$90/12 -> 10 | ... AN12: =AN$7*$B$90/12 -> 20 | AO12: H | AP12: D-16 : année 1 = 7 privatisations (budget du 27/10). À partir de l'année 2 : 40 par ville active et par an (paramètre B86), soit villes actives × 40 / 12 par mois
A13: Nombre total de soirées | B13: =SUM(E13:P13) -> 16 | C13: =SUM(Q13:AB13) -> 153 | D13: =SUM(AC13:AN13) -> 306 | E13: =E11+E12 -> 0 | F13: =F11+F12 -> 0 | G13: =G11+G12 -> 1 | H13: =H11+H12 -> 1 | I13: =I11+I12 -> 1 | J13: =J11+J12 -> 2 | K13: =K11+K12 -> 2 | L13: =L11+L12 -> 2 | ... AN13: =AN11+AN12 -> 26
A14: dont soirées « place à l'unité » hors Paris, en France | B14: =SUM(E14:P14) -> 0 | C14: =SUM(Q14:AB14) -> 11 | D14: =SUM(AC14:AN14) -> 22 | E14: 0 | F14: 0 | G14: 0 | H14: 0 | I14: 0 | J14: 0 | K14: 0 | L14: 0 | M14: 0 | N14: 0 | O14: 0 | P14: 0 | Q14: 1 | R14: 1 | S14: 1 | T14: 1 | U14: 1 | V14: 1 | W14: 1 | X14: 1 | Y14: 1 | Z14: 0 | AA14: 1 | AB14: 1 | AC14: 2 | AD14: 2 | AE14: 2 | AF14: 2 | AG14: 2 | AH14: 2 | AI14: 2 | AJ14: 2 | AK14: 2 | AL14: 0 | AM14: 2 | AN14: 2 | AO14: H | AP14: Soirées « place à l'unité » des villes 2 et 4 ; seules ces soirées portent des frais de déplacement (ligne 29)
A15: dont soirées « place à l'unité » hors Paris, à l'étranger | B15: =SUM(E15:P15) -> 0 | C15: =SUM(Q15:AB15) -> 11 | D15: =SUM(AC15:AN15) -> 33 | E15: 0 | F15: 0 | G15: 0 | H15: 0 | I15: 0 | J15: 0 | K15: 0 | L15: 0 | M15: 0 | N15: 0 | O15: 0 | P15: 0 | Q15: 1 | R15: 1 | S15: 1 | T15: 1 | U15: 1 | V15: 1 | W15: 1 | X15: 1 | Y15: 1 | Z15: 0 | AA15: 1 | AB15: 1 | AC15: 3 | AD15: 3 | AE15: 3 | AF15: 3 | AG15: 3 | AH15: 3 | AI15: 3 | AJ15: 3 | AK15: 3 | AL15: 0 | AM15: 3 | AN15: 3 | AO15: H | AP15: Soirées « place à l'unité » des villes 3, 5 et 6. Prix, coûts et TVA supposés identiques à Paris (H)
A16: dont privatisations hors Paris, en France | B16: =SUM(E16:P16) -> 0 | C16: =SUM(Q16:AB16) -> 40 | D16: =SUM(AC16:AN16) -> 80 | E16: 0 | F16: 0 | G16: 0 | H16: 0 | I16: 0 | J16: 0 | K16: 0 | L16: 0 | M16: 0 | N16: 0 | O16: 0 | P16: 0 | Q16: =((Q$7>=2)+(Q$7>=4))*$B$90/12 -> 3.3333333 | R16: =((R$7>=2)+(R$7>=4))*$B$90/12 -> 3.3333333 | S16: =((S$7>=2)+(S$7>=4))*$B$90/12 -> 3.3333333 | T16: =((T$7>=2)+(T$7>=4))*$B$90/12 -> 3.3333333 | U16: =((U$7>=2)+(U$7>=4))*$B$90/12 -> 3.3333333 | V16: =((V$7>=2)+(V$7>=4))*$B$90/12 -> 3.3333333 | W16: =((W$7>=2)+(W$7>=4))*$B$90/12 -> 3.3333333 | X16: =((X$7>=2)+(X$7>=4))*$B$90/12 -> 3.3333333 | ... AN16: =((AN$7>=2)+(AN$7>=4))*$B$90/12 -> 6.6666667 | AO16: F | AP16: Privatisations (ligne 12) des villes 2 et 4 : 40 par ville et par an (B86). Pas de frais de déplacement de production (décision du 28/10/2026)
A17: dont privatisations hors Paris, à l'étranger | B17: =SUM(E17:P17) -> 0 | C17: =SUM(Q17:AB17) -> 40 | D17: =SUM(AC17:AN17) -> 120 | E17: 0 | F17: 0 | G17: 0 | H17: 0 | I17: 0 | J17: 0 | K17: 0 | L17: 0 | M17: 0 | N17: 0 | O17: 0 | P17: 0 | Q17: =((Q$7>=3)+(Q$7>=5)+(Q$7>=6))*$B$90/12 -> 3.3333333 | R17: =((R$7>=3)+(R$7>=5)+(R$7>=6))*$B$90/12 -> 3.3333333 | S17: =((S$7>=3)+(S$7>=5)+(S$7>=6))*$B$90/12 -> 3.3333333 | T17: =((T$7>=3)+(T$7>=5)+(T$7>=6))*$B$90/12 -> 3.3333333 | U17: =((U$7>=3)+(U$7>=5)+(U$7>=6))*$B$90/12 -> 3.3333333 | V17: =((V$7>=3)+(V$7>=5)+(V$7>=6))*$B$90/12 -> 3.3333333 | W17: =((W$7>=3)+(W$7>=5)+(W$7>=6))*$B$90/12 -> 3.3333333 | X17: =((X$7>=3)+(X$7>=5)+(X$7>=6))*$B$90/12 -> 3.3333333 | ... AN17: =((AN$7>=3)+(AN$7>=5)+(AN$7>=6))*$B$90/12 -> 10 | AO17: F | AP17: Privatisations (ligne 12) des villes 3, 5 et 6 : idem. Pas de frais de déplacement de production ; prix, coûts et TVA identiques à Paris (H)
A18: Pilote Premier soir (inclus ligne 8) | B18: =SUM(E18:P18) -> 1 | C18: =SUM(Q18:AB18) -> 0 | D18: =SUM(AC18:AN18) -> 0 | E18: 0 | F18: 0 | G18: 1 | H18: 0 | I18: 0 | J18: 0 | K18: 0 | L18: 0 | M18: 0 | N18: 0 | O18: 0 | P18: 0 | Q18: 0 | R18: 0 | S18: 0 | T18: 0 | U18: 0 | V18: 0 | W18: 0 | X18: 0 | Y18: 0 | Z18: 0 | AA18: 0 | AB18: 0 | AC18: 0 | AD18: 0 | AE18: 0 | AF18: 0 | AG18: 0 | AH18: 0 | AI18: 0 | AJ18: 0 | AK18: 0 | AL18: 0 | AM18: 0 | AN18: 0 | AO18: P | AP18: 5 PRODUIT, plan des deux soirées pilotes
A19: Pilote La Grande Nuit (inclus ligne 10) | B19: =SUM(E19:P19) -> 1 | C19: =SUM(Q19:AB19) -> 0 | D19: =SUM(AC19:AN19) -> 0 | E19: 0 | F19: 0 | G19: 0 | H19: 1 | I19: 0 | J19: 0 | K19: 0 | L19: 0 | M19: 0 | N19: 0 | O19: 0 | P19: 0 | Q19: 0 | R19: 0 | S19: 0 | T19: 0 | U19: 0 | V19: 0 | W19: 0 | X19: 0 | Y19: 0 | Z19: 0 | AA19: 0 | AB19: 0 | AC19: 0 | AD19: 0 | AE19: 0 | AF19: 0 | AG19: 0 | AH19: 0 | AI19: 0 | AJ19: 0 | AK19: 0 | AL19: 0 | AM19: 0 | AN19: 0 | AO19: P | AP19: Idem
A20: Coordinateurs nécessaires (effectif) | B20: =MAX(E20:P20) -> 0 | C20: =MAX(Q20:AB20) -> 3 | D20: =MAX(AC20:AN20) -> 6 | E20: {=ROUNDUP(INDEX($B$13:$D$13,INT((E$4-1)/12)+1)/(52*'Ressources humaines'!$C$5),0)*(E$4>='Ressources humaines'!$D$9)} -> 0 | F20: {=ROUNDUP(INDEX($B$13:$D$13,INT((F$4-1)/12)+1)/(52*'Ressources humaines'!$C$5),0)*(F$4>='Ressources humaines'!$D$9)} -> 0 | G20: {=ROUNDUP(INDEX($B$13:$D$13,INT((G$4-1)/12)+1)/(52*'Ressources humaines'!$C$5),0)*(G$4>='Ressources humaines'!$D$9)} -> 0 | H20: {=ROUNDUP(INDEX($B$13:$D$13,INT((H$4-1)/12)+1)/(52*'Ressources humaines'!$C$5),0)*(H$4>='Ressources humaines'!$D$9)} -> 0 | I20: {=ROUNDUP(INDEX($B$13:$D$13,INT((I$4-1)/12)+1)/(52*'Ressources humaines'!$C$5),0)*(I$4>='Ressources humaines'!$D$9)} -> 0 | J20: {=ROUNDUP(INDEX($B$13:$D$13,INT((J$4-1)/12)+1)/(52*'Ressources humaines'!$C$5),0)*(J$4>='Ressources humaines'!$D$9)} -> 0 | K20: {=ROUNDUP(INDEX($B$13:$D$13,INT((K$4-1)/12)+1)/(52*'Ressources humaines'!$C$5),0)*(K$4>='Ressources humaines'!$D$9)} -> 0 | L20: {=ROUNDUP(INDEX($B$13:$D$13,INT((L$4-1)/12)+1)/(52*'Ressources humaines'!$C$5),0)*(L$4>='Ressources humaines'!$D$9)} -> 0 | ... AN20: {=ROUNDUP(INDEX($B$13:$D$13,INT((AN$4-1)/12)+1)/(52*'Ressources humaines'!$C$5),0)*(AN$4>='Ressources humaines'!$D$9)} -> 6 | AO20: F | AP20: Arrondi supérieur de (soirées de l'année, ligne 13) ÷ (52 semaines × événements par coordinateur, Ressources humaines C5), à partir du premier mois payé (Ressources humaines D9)
A21: Commerciaux nécessaires (effectif) | B21: =MAX(E21:P21) -> 0 | C21: =MAX(Q21:AB21) -> 0 | D21: =MAX(AC21:AN21) -> 6 | E21: =E$7*'Ressources humaines'!$C$6*(E$4>='Ressources humaines'!$D$10) -> 0 | F21: =F$7*'Ressources humaines'!$C$6*(F$4>='Ressources humaines'!$D$10) -> 0 | G21: =G$7*'Ressources humaines'!$C$6*(G$4>='Ressources humaines'!$D$10) -> 0 | H21: =H$7*'Ressources humaines'!$C$6*(H$4>='Ressources humaines'!$D$10) -> 0 | I21: =I$7*'Ressources humaines'!$C$6*(I$4>='Ressources humaines'!$D$10) -> 0 | J21: =J$7*'Ressources humaines'!$C$6*(J$4>='Ressources humaines'!$D$10) -> 0 | K21: =K$7*'Ressources humaines'!$C$6*(K$4>='Ressources humaines'!$D$10) -> 0 | L21: =L$7*'Ressources humaines'!$C$6*(L$4>='Ressources humaines'!$D$10) -> 0 | ... AN21: =AN$7*'Ressources humaines'!$C$6*(AN$4>='Ressources humaines'!$D$10) -> 6 | AO21: F | AP21: Villes actives (ligne 7) × commerciaux par ville (Ressources humaines C6), à partir du premier mois payé (Ressources humaines D10)
A22: Effectif total payé (postes) | B22: =MAX(E22:P22) -> 0 | C22: =MAX(Q22:AB22) -> 3 | D22: =MAX(AC22:AN22) -> 15 | E22: =E$20+E$21+'Ressources humaines'!$B$8*(E$4>='Ressources humaines'!$D$8)+'Ressources humaines'!$B$11*(E$4>='Ressources humaines'!$D$11) -> 0 | F22: =F$20+F$21+'Ressources humaines'!$B$8*(F$4>='Ressources humaines'!$D$8)+'Ressources humaines'!$B$11*(F$4>='Ressources humaines'!$D$11) -> 0 | G22: =G$20+G$21+'Ressources humaines'!$B$8*(G$4>='Ressources humaines'!$D$8)+'Ressources humaines'!$B$11*(G$4>='Ressources humaines'!$D$11) -> 0 | H22: =H$20+H$21+'Ressources humaines'!$B$8*(H$4>='Ressources humaines'!$D$8)+'Ressources humaines'!$B$11*(H$4>='Ressources humaines'!$D$11) -> 0 | I22: =I$20+I$21+'Ressources humaines'!$B$8*(I$4>='Ressources humaines'!$D$8)+'Ressources humaines'!$B$11*(I$4>='Ressources humaines'!$D$11) -> 0 | J22: =J$20+J$21+'Ressources humaines'!$B$8*(J$4>='Ressources humaines'!$D$8)+'Ressources humaines'!$B$11*(J$4>='Ressources humaines'!$D$11) -> 0 | K22: =K$20+K$21+'Ressources humaines'!$B$8*(K$4>='Ressources humaines'!$D$8)+'Ressources humaines'!$B$11*(K$4>='Ressources humaines'!$D$11) -> 0 | L22: =L$20+L$21+'Ressources humaines'!$B$8*(L$4>='Ressources humaines'!$D$8)+'Ressources humaines'!$B$11*(L$4>='Ressources humaines'!$D$11) -> 0 | ... AN22: =AN$20+AN$21+'Ressources humaines'!$B$8*(AN$4>='Ressources humaines'!$D$8)+'Ressources humaines'!$B$11*(AN$4>='Ressources humaines'!$D$11) -> 15 | AO22: F | AP22: Coordinateurs + commerciaux + fondateurs rémunérés + manager, à partir de leur premier mois payé (onglet Ressources humaines). Sert aux locaux et aux logiciels (lignes 39 et 40)
A23: 2. Chiffre d'affaires et coûts directs
A24: Chiffre d'affaires des places à l'unité | B24: =SUM(E24:P24) -> 125892.86 | C24: =SUM(Q24:AB24) -> 461607.14 | D24: =SUM(AC24:AN24) -> 923214.29 | E24: =E8*'Prix et marges'!$C$17+E9*'Prix et marges'!$D$17+E10*'Prix et marges'!$E$17 -> 0 | F24: =F8*'Prix et marges'!$C$17+F9*'Prix et marges'!$D$17+F10*'Prix et marges'!$E$17 -> 0 | G24: =G8*'Prix et marges'!$C$17+G9*'Prix et marges'!$D$17+G10*'Prix et marges'!$E$17 -> 10357.143 | H24: =H8*'Prix et marges'!$C$17+H9*'Prix et marges'!$D$17+H10*'Prix et marges'!$E$17 -> 18482.143 | I24: =I8*'Prix et marges'!$C$17+I9*'Prix et marges'!$D$17+I10*'Prix et marges'!$E$17 -> 13125 | J24: =J8*'Prix et marges'!$C$17+J9*'Prix et marges'!$D$17+J10*'Prix et marges'!$E$17 -> 10357.143 | K24: =K8*'Prix et marges'!$C$17+K9*'Prix et marges'!$D$17+K10*'Prix et marges'!$E$17 -> 18482.143 | L24: =L8*'Prix et marges'!$C$17+L9*'Prix et marges'!$D$17+L10*'Prix et marges'!$E$17 -> 13125 | ... AN24: =AN8*'Prix et marges'!$C$17+AN9*'Prix et marges'!$D$17+AN10*'Prix et marges'!$E$17 -> 83928.571 | AP24: Nombre de soirées × chiffre d'affaires d'une soirée (Prix et marges, ligne 17)
A25: Chiffre d'affaires des privatisations | B25: =SUM(E25:P25) -> 93750 | C25: =SUM(Q25:AB25) -> 1607142.9 | D25: =SUM(AC25:AN25) -> 3214285.7 | E25: =E12*'Prix et marges'!$F$17 -> 0 | F25: =F12*'Prix et marges'!$F$17 -> 0 | G25: =G12*'Prix et marges'!$F$17 -> 0 | H25: =H12*'Prix et marges'!$F$17 -> 0 | I25: =I12*'Prix et marges'!$F$17 -> 0 | J25: =J12*'Prix et marges'!$F$17 -> 13392.857 | K25: =K12*'Prix et marges'!$F$17 -> 13392.857 | L25: =L12*'Prix et marges'!$F$17 -> 13392.857 | ... AN25: =AN12*'Prix et marges'!$F$17 -> 267857.14
A26: Chiffre d'affaires | B26: =SUM(E26:P26) -> 219642.86 | C26: =SUM(Q26:AB26) -> 2068750 | D26: =SUM(AC26:AN26) -> 4137500 | E26: =E24+E25 -> 0 | F26: =F24+F25 -> 0 | G26: =G24+G25 -> 10357.143 | H26: =H24+H25 -> 18482.143 | I26: =I24+I25 -> 13125 | J26: =J24+J25 -> 23750 | K26: =K24+K25 -> 31875 | L26: =L24+L25 -> 26517.857 | ... AN26: =AN24+AN25 -> 351785.71
A27: Coûts directs des soirées | B27: =SUM(E27:P27) -> 161190.36 | C27: =SUM(Q27:AB27) -> 1433293.2 | D27: =SUM(AC27:AN27) -> 2866586.4 | E27: =E8*'Prix et marges'!$C$34+E9*'Prix et marges'!$D$34+E10*'Prix et marges'!$E$34+E12*'Prix et marges'!$F$34 -> 0 | F27: =F8*'Prix et marges'!$C$34+F9*'Prix et marges'!$D$34+F10*'Prix et marges'!$E$34+F12*'Prix et marges'!$F$34 -> 0 | G27: =G8*'Prix et marges'!$C$34+G9*'Prix et marges'!$D$34+G10*'Prix et marges'!$E$34+G12*'Prix et marges'!$F$34 -> 7569.2857 | H27: =H8*'Prix et marges'!$C$34+H9*'Prix et marges'!$D$34+H10*'Prix et marges'!$E$34+H12*'Prix et marges'!$F$34 -> 14416.25 | I27: =I8*'Prix et marges'!$C$34+I9*'Prix et marges'!$D$34+I10*'Prix et marges'!$E$34+I12*'Prix et marges'!$F$34 -> 10911.25 | J27: =J8*'Prix et marges'!$C$34+J9*'Prix et marges'!$D$34+J10*'Prix et marges'!$E$34+J12*'Prix et marges'!$F$34 -> 16497.857 | K27: =K8*'Prix et marges'!$C$34+K9*'Prix et marges'!$D$34+K10*'Prix et marges'!$E$34+K12*'Prix et marges'!$F$34 -> 23344.821 | L27: =L8*'Prix et marges'!$C$34+L9*'Prix et marges'!$D$34+L10*'Prix et marges'!$E$34+L12*'Prix et marges'!$F$34 -> 19839.821 | ... AN27: =AN8*'Prix et marges'!$C$34+AN9*'Prix et marges'!$D$34+AN10*'Prix et marges'!$E$34+AN12*'Prix et marges'!$F$34 -> 244365 | AP27: Nombre de soirées × coûts directs d'une soirée (Prix et marges, ligne 34) : lieu, chef, matières, boissons, équipe (D-06), ménage, assurance, décor, frais et commissions ; photographe à 0 (D-08)
A28: Surcoût d'équipe des pilotes | B28: =SUM(E28:P28) -> 1155 | C28: =SUM(Q28:AB28) -> 0 | D28: =SUM(AC28:AN28) -> 0 | E28: =E18*Staffing!$D$40+E19*Staffing!$F$40 -> 0 | F28: =F18*Staffing!$D$40+F19*Staffing!$F$40 -> 0 | G28: =G18*Staffing!$D$40+G19*Staffing!$F$40 -> 700 | H28: =H18*Staffing!$D$40+H19*Staffing!$F$40 -> 455 | I28: =I18*Staffing!$D$40+I19*Staffing!$F$40 -> 0 | J28: =J18*Staffing!$D$40+J19*Staffing!$F$40 -> 0 | K28: =K18*Staffing!$D$40+K19*Staffing!$F$40 -> 0 | L28: =L18*Staffing!$D$40+L19*Staffing!$F$40 -> 0 | ... AN28: =AN18*Staffing!$D$40+AN19*Staffing!$F$40 -> 0 | AO28: H | AP28: Onglet Staffing, ligne 40 (équipe complète S0 à 24 et 20 couverts). F Les Opérations proposent 490 € au total (note du 28/10, branche non fusionnée) : non repris
A29: Déplacements de production hors Paris | B29: =SUM(E29:P29) -> 0 | C29: =SUM(Q29:AB29) -> 11000 | D29: =SUM(AC29:AN29) -> 29700 | E29: =E14*$B$84+E15*$B$85 -> 0 | F29: =F14*$B$84+F15*$B$85 -> 0 | G29: =G14*$B$84+G15*$B$85 -> 0 | H29: =H14*$B$84+H15*$B$85 -> 0 | I29: =I14*$B$84+I15*$B$85 -> 0 | J29: =J14*$B$84+J15*$B$85 -> 0 | K29: =K14*$B$84+K15*$B$85 -> 0 | L29: =L14*$B$84+L15*$B$85 -> 0 | ... AN29: =AN14*$B$84+AN15*$B$85 -> 2700 | AO29: H | AP29: Responsable de production : train et 1 nuit en France, avion et 1 nuit à l'étranger, par soirée (Paramètres). Le personnel est recruté sur place (D-07) | AQ29: 0.1
A30: Total des coûts directs | B30: =SUM(E30:P30) -> 162345.36 | C30: =SUM(Q30:AB30) -> 1444293.2 | D30: =SUM(AC30:AN30) -> 2896286.4 | E30: =E27+E28+E29 -> 0 | F30: =F27+F28+F29 -> 0 | G30: =G27+G28+G29 -> 8269.2857 | H30: =H27+H28+H29 -> 14871.25 | I30: =I27+I28+I29 -> 10911.25 | J30: =J27+J28+J29 -> 16497.857 | K30: =K27+K28+K29 -> 23344.821 | L30: =L27+L28+L29 -> 19839.821 | ... AN30: =AN27+AN28+AN29 -> 247065
A31: Marge sur coûts directs | B31: =SUM(E31:P31) -> 57297.5 | C31: =SUM(Q31:AB31) -> 624456.79 | D31: =SUM(AC31:AN31) -> 1241213.6 | E31: =E26-E30 -> 0 | F31: =F26-F30 -> 0 | G31: =G26-G30 -> 2087.8571 | H31: =H26-H30 -> 3610.8929 | I31: =I26-I30 -> 2213.75 | J31: =J26-J30 -> 7252.1429 | K31: =K26-K30 -> 8530.1786 | L31: =L26-L30 -> 6678.0357 | ... AN31: =AN26-AN30 -> 104720.71
A32: 3. Frais généraux : ressources humaines (onglet Ressources humaines)
A33: ='Ressources humaines'!A8 -> Fondateurs (rémunération) | B33: =SUM(E33:P33) -> 0 | C33: =SUM(Q33:AB33) -> 0 | D33: =SUM(AC33:AN33) -> 87000 | E33: ='Ressources humaines'!$B$8*'Ressources humaines'!$C$8*(1+'Ressources humaines'!$C$4)*(E$4>='Ressources humaines'!$D$8) -> 0 | F33: ='Ressources humaines'!$B$8*'Ressources humaines'!$C$8*(1+'Ressources humaines'!$C$4)*(F$4>='Ressources humaines'!$D$8) -> 0 | G33: ='Ressources humaines'!$B$8*'Ressources humaines'!$C$8*(1+'Ressources humaines'!$C$4)*(G$4>='Ressources humaines'!$D$8) -> 0 | H33: ='Ressources humaines'!$B$8*'Ressources humaines'!$C$8*(1+'Ressources humaines'!$C$4)*(H$4>='Ressources humaines'!$D$8) -> 0 | I33: ='Ressources humaines'!$B$8*'Ressources humaines'!$C$8*(1+'Ressources humaines'!$C$4)*(I$4>='Ressources humaines'!$D$8) -> 0 | J33: ='Ressources humaines'!$B$8*'Ressources humaines'!$C$8*(1+'Ressources humaines'!$C$4)*(J$4>='Ressources humaines'!$D$8) -> 0 | K33: ='Ressources humaines'!$B$8*'Ressources humaines'!$C$8*(1+'Ressources humaines'!$C$4)*(K$4>='Ressources humaines'!$D$8) -> 0 | L33: ='Ressources humaines'!$B$8*'Ressources humaines'!$C$8*(1+'Ressources humaines'!$C$4)*(L$4>='Ressources humaines'!$D$8) -> 0 | ... AN33: ='Ressources humaines'!$B$8*'Ressources humaines'!$C$8*(1+'Ressources humaines'!$C$4)*(AN$4>='Ressources humaines'!$D$8) -> 7250 | AO33: H | AP33: Effectif × salaire brut × (1 + charges), à partir du premier mois payé (onglet Ressources humaines)
A34: ='Ressources humaines'!A9 -> Coordinateur ou coordinatrice d'événements | B34: =SUM(E34:P34) -> 0 | C34: =SUM(Q34:AB34) -> 97458.444 | D34: =SUM(AC34:AN34) -> 194916.89 | E34: =E$20*'Ressources humaines'!$C$9*(1+'Ressources humaines'!$C$4) -> 0 | F34: =F$20*'Ressources humaines'!$C$9*(1+'Ressources humaines'!$C$4) -> 0 | G34: =G$20*'Ressources humaines'!$C$9*(1+'Ressources humaines'!$C$4) -> 0 | H34: =H$20*'Ressources humaines'!$C$9*(1+'Ressources humaines'!$C$4) -> 0 | I34: =I$20*'Ressources humaines'!$C$9*(1+'Ressources humaines'!$C$4) -> 0 | J34: =J$20*'Ressources humaines'!$C$9*(1+'Ressources humaines'!$C$4) -> 0 | K34: =K$20*'Ressources humaines'!$C$9*(1+'Ressources humaines'!$C$4) -> 0 | L34: =L$20*'Ressources humaines'!$C$9*(1+'Ressources humaines'!$C$4) -> 0 | ... AN34: =AN$20*'Ressources humaines'!$C$9*(1+'Ressources humaines'!$C$4) -> 16243.074 | AO34: F | AP34: Effectif ligne 20 × salaire brut × (1 + charges) (onglet Ressources humaines)
A35: ='Ressources humaines'!A10 -> Commercial ou commerciale entreprises | B35: =SUM(E35:P35) -> 0 | C35: =SUM(Q35:AB35) -> 0 | D35: =SUM(AC35:AN35) -> 292320 | E35: =E$21*'Ressources humaines'!$C$10*(1+'Ressources humaines'!$C$4) -> 0 | F35: =F$21*'Ressources humaines'!$C$10*(1+'Ressources humaines'!$C$4) -> 0 | G35: =G$21*'Ressources humaines'!$C$10*(1+'Ressources humaines'!$C$4) -> 0 | H35: =H$21*'Ressources humaines'!$C$10*(1+'Ressources humaines'!$C$4) -> 0 | I35: =I$21*'Ressources humaines'!$C$10*(1+'Ressources humaines'!$C$4) -> 0 | J35: =J$21*'Ressources humaines'!$C$10*(1+'Ressources humaines'!$C$4) -> 0 | K35: =K$21*'Ressources humaines'!$C$10*(1+'Ressources humaines'!$C$4) -> 0 | L35: =L$21*'Ressources humaines'!$C$10*(1+'Ressources humaines'!$C$4) -> 0 | ... AN35: =AN$21*'Ressources humaines'!$C$10*(1+'Ressources humaines'!$C$4) -> 24360 | AO35: F | AP35: Effectif ligne 21 × salaire brut × (1 + charges) (onglet Ressources humaines)
A36: ='Ressources humaines'!A11 -> Manager | B36: =SUM(E36:P36) -> 0 | C36: =SUM(Q36:AB36) -> 0 | D36: =SUM(AC36:AN36) -> 69600 | E36: ='Ressources humaines'!$B$11*'Ressources humaines'!$C$11*(1+'Ressources humaines'!$C$4)*(E$4>='Ressources humaines'!$D$11) -> 0 | F36: ='Ressources humaines'!$B$11*'Ressources humaines'!$C$11*(1+'Ressources humaines'!$C$4)*(F$4>='Ressources humaines'!$D$11) -> 0 | G36: ='Ressources humaines'!$B$11*'Ressources humaines'!$C$11*(1+'Ressources humaines'!$C$4)*(G$4>='Ressources humaines'!$D$11) -> 0 | H36: ='Ressources humaines'!$B$11*'Ressources humaines'!$C$11*(1+'Ressources humaines'!$C$4)*(H$4>='Ressources humaines'!$D$11) -> 0 | I36: ='Ressources humaines'!$B$11*'Ressources humaines'!$C$11*(1+'Ressources humaines'!$C$4)*(I$4>='Ressources humaines'!$D$11) -> 0 | J36: ='Ressources humaines'!$B$11*'Ressources humaines'!$C$11*(1+'Ressources humaines'!$C$4)*(J$4>='Ressources humaines'!$D$11) -> 0 | K36: ='Ressources humaines'!$B$11*'Ressources humaines'!$C$11*(1+'Ressources humaines'!$C$4)*(K$4>='Ressources humaines'!$D$11) -> 0 | L36: ='Ressources humaines'!$B$11*'Ressources humaines'!$C$11*(1+'Ressources humaines'!$C$4)*(L$4>='Ressources humaines'!$D$11) -> 0 | ... AN36: ='Ressources humaines'!$B$11*'Ressources humaines'!$C$11*(1+'Ressources humaines'!$C$4)*(AN$4>='Ressources humaines'!$D$11) -> 5800 | AO36: H | AP36: Effectif × salaire brut × (1 + charges), à partir du premier mois payé (onglet Ressources humaines)
A37: Total ressources humaines | B37: =SUM(E37:P37) -> 0 | C37: =SUM(Q37:AB37) -> 97458.444 | D37: =SUM(AC37:AN37) -> 643836.89 | E37: =SUM(E33:E36) -> 0 | F37: =SUM(F33:F36) -> 0 | G37: =SUM(G33:G36) -> 0 | H37: =SUM(H33:H36) -> 0 | I37: =SUM(I33:I36) -> 0 | J37: =SUM(J33:J36) -> 0 | K37: =SUM(K33:K36) -> 0 | L37: =SUM(L33:L36) -> 0 | ... AN37: =SUM(AN33:AN36) -> 53653.074
A38: 4. Frais généraux : fonctionnement, marketing, ventes
A39: Locaux et bureaux | B39: =SUM(E39:P39) -> 0 | C39: =SUM(Q39:AB39) -> 10800 | D39: =SUM(AC39:AN39) -> 54000 | E39: =E$22*$B$91 -> 0 | F39: =F$22*$B$91 -> 0 | G39: =G$22*$B$91 -> 0 | H39: =H$22*$B$91 -> 0 | I39: =I$22*$B$91 -> 0 | J39: =J$22*$B$91 -> 0 | K39: =K$22*$B$91 -> 0 | L39: =L$22*$B$91 -> 0 | ... AN39: =AN$22*$B$91 -> 4500 | AO39: F | AP39: Effectif total payé (ligne 22) × coût du coworking par poste (B91). Travail à distance tant qu'aucun poste n'est payé | AQ39: =TVA!$C$30 -> 0.2
A40: Logiciels et outils (site, billetterie, fichier clients) | B40: =SUM(E40:P40) -> 960 | C40: =SUM(Q40:AB40) -> 2760 | D40: =SUM(AC40:AN40) -> 9960 | E40: =$B$92+E$22*$B$93 -> 80 | F40: =$B$92+F$22*$B$93 -> 80 | G40: =$B$92+G$22*$B$93 -> 80 | H40: =$B$92+H$22*$B$93 -> 80 | I40: =$B$92+I$22*$B$93 -> 80 | J40: =$B$92+J$22*$B$93 -> 80 | K40: =$B$92+K$22*$B$93 -> 80 | L40: =$B$92+L$22*$B$93 -> 80 | ... AN40: =$B$92+AN$22*$B$93 -> 830 | AO40: F | AP40: Socle mensuel (B92) + effectif total payé (ligne 22) × licences par poste (B93) | AQ40: =TVA!$C$31 -> 0.2
...

Sheet TVA
A1: TVA : taux et règles (calcul mois par mois dans « Budget 36 mois »)
A2: Effet de la TVA sur la trésorerie. Le compte de résultat reste hors taxes : la TVA ne change ni la marge ni le résultat, seulement le calendrier des encaissements et des décaissements.
A4: Paramètre | B4: Choix retenu | D4: Nature | E4: Source et explication
A5: Régime | B5: Réel normal, déclaration mensuelle | D5: H | E5: H : la TVA nette d'un mois est reversée à l'État le mois suivant ; à confirmer par l'expert-comptable (donnée n° 6)
A6: Crédit de TVA | B6: Reporté sur les mois suivants | D6: H | E6: H prudente : aucune demande de remboursement. Un remboursement du crédit peut être demandé ; il améliorerait la trésorerie ; à confirmer par l'expert-comptable (donnée n° 6)
A7: TVA collectée sur les ventes | B7: Taux moyen de chaque offre (Prix et marges, ligne 12) | D7: H | E7: H : 12 % (10 % sur la restauration, 20 % sur les boissons alcoolisées), déjà utilisé pour passer du TTC au HT
A9: Coût d'une soirée | B9: Ligne de Prix et marges | C9: Taux de TVA déductible | D9: Nature | E9: Source et explication
A10: Lieu (mise à disposition) | B10: 19 | C10: 0.2 | D10: H | E10: H : location facturée avec TVA à 20 %
A11: Chef (cachet) | B11: 22 | C11: 0 | D11: H | E11: H prudente : chef indépendant en franchise de TVA, qui ne facture pas de TVA
A12: Matières premières | B12: 23 × convives | C12: 0.055 | D12: H | E12: H : taux réduit des produits alimentaires (5,5 %)
A13: Boissons (vins, alcools) | B13: 24 × convives | C13: 0.2 | D13: H | E13: H : boissons alcoolisées à 20 %
A14: Équipe (extras, brigade, plonge) | B14: 26 et surcoût des pilotes | C14: 0.2 | D14: H | E14: H : extras facturés par une agence avec TVA à 20 % ; 0 % s'ils étaient salariés en direct
A15: Ménage | B15: 27 | C15: 0.2 | D15: H | E15: H
A16: Assurance de la soirée | B16: 28 | C16: 0 | D16: H | E16: H : assurance exonérée de TVA
A17: Décor et fleurs | B17: 29 | C17: 0.2 | D17: H | E17: H
A18: Frais de paiement | B18: 30 × chiffre d'affaires | C18: 0 | D18: H | E18: H : services financiers exonérés de TVA
A19: Commission d'apporteur | B19: 31 × chiffre d'affaires | C19: 0.2 | D19: H | E19: H
A20: Photographe (supprimé, D-08) | B20: 33 | C20: 0.2 | D20: H | E20: H : 0 % si le photographe est en franchise de TVA
A22: Par soirée | C22: Premier soir | D22: Le Voyage | E22: La Grande Nuit | F22: Privatisation
A23: Chiffre d'affaires HT | C23: ='Prix et marges'!C17 -> 10357.143 | D23: ='Prix et marges'!D17 -> 13125 | E23: ='Prix et marges'!E17 -> 18482.143 | F23: ='Prix et marges'!F17 -> 13392.857
A24: Taux de TVA collectée | C24: ='Prix et marges'!C12 -> 0.12 | D24: ='Prix et marges'!D12 -> 0.12 | E24: ='Prix et marges'!E12 -> 0.12 | F24: ='Prix et marges'!F12 -> 0.12
A25: TVA collectée | C25: =C23*C24 -> 1242.8571 | D25: =D23*D24 -> 1575 | E25: =E23*E24 -> 2217.8571 | F25: =F23*F24 -> 1607.1429
A26: TVA déductible sur les coûts directs | C26: ='Prix et marges'!C19*$C$10+'Prix et marges'!C22*$C$11+'Prix et marges'!C9*'Prix et marges'!C23*$C$12+'Prix et marges'!C9*'Prix et marges'!C24*$C$13+'Prix et marges'!C26*$C$14+'Prix et marges'!C27*$C$15+'Prix et marges'!C28*$C$16+'Prix et marges'!C29*$C$17+'Prix et marges'!C30*'Prix et marges'!C17*$C$18+'Prix et marges'!C31*'Prix et marges'!C17*$C$19+'Prix et marges'!C33*$C$20 -> 941.71429 | D26: ='Prix et marges'!D19*$C$10+'Prix et marges'!D22*$C$11+'Prix et marges'!D9*'Prix et marges'!D23*$C$12+'Prix et marges'!D9*'Prix et marges'!D24*$C$13+'Prix et marges'!D26*$C$14+'Prix et marges'!D27*$C$15+'Prix et marges'!D28*$C$16+'Prix et marges'!D29*$C$17+'Prix et marges'!D30*'Prix et marges'!D17*$C$18+'Prix et marges'!D31*'Prix et marges'!D17*$C$19+'Prix et marges'!D33*$C$20 -> 1355 | E26: ='Prix et marges'!E19*$C$10+'Prix et marges'!E22*$C$11+'Prix et marges'!E9*'Prix et marges'!E23*$C$12+'Prix et marges'!E9*'Prix et marges'!E24*$C$13+'Prix et marges'!E26*$C$14+'Prix et marges'!E27*$C$15+'Prix et marges'!E28*$C$16+'Prix et marges'!E29*$C$17+'Prix et marges'!E30*'Prix et marges'!E17*$C$18+'Prix et marges'!E31*'Prix et marges'!E17*$C$19+'Prix et marges'!E33*$C$20 -> 1702.6071 | F26: ='Prix et marges'!F19*$C$10+'Prix et marges'!F22*$C$11+'Prix et marges'!F9*'Prix et marges'!F23*$C$12+'Prix et marges'!F9*'Prix et marges'!F24*$C$13+'Prix et marges'!F26*$C$14+'Prix et marges'!F27*$C$15+'Prix et marges'!F28*$C$16+'Prix et marges'!F29*$C$17+'Prix et marges'!F30*'Prix et marges'!F17*$C$18+'Prix et marges'!F31*'Prix et marges'!F17*$C$19+'Prix et marges'!F33*$C$20 -> 1091.2143
A27: TVA nette de la soirée | C27: =C25-C26 -> 301.14286 | D27: =D25-D26 -> 220 | E27: =E25-E26 -> 515.25 | F27: =F25-F26 -> 515.92857
A29: Frais généraux et investissements | B29: Ligne du budget | C29: Taux de TVA déductible | D29: Nature | E29: Source et explication
A30: Locaux | B30: Budget 36 mois, 33 | C30: 0.2 | D30: H | E30: H
A31: Logiciels et outils | B31: Budget 36 mois, 34 | C31: 0.2 | D31: H | E31: H
A32: Marketing et communication | B32: Budget 36 mois, 35 | C32: 0.2 | D32: H | E32: H : dîners de concierges au restaurant à 10 %, le reste à 20 % ; 20 % retenu
A33: Protection juridique et assurance de la société (2 % du CA) | B33: Budget 36 mois, 42 | C33: 0 | D33: H | E33: H : assurance exonérée
A34: Honoraires | B34: Budget 36 mois, 43 | C34: 0.2 | D34: H | E34: H
A35: Banque | B35: Budget 36 mois, 44 | C35: 0 | D35: H | E35: H : services bancaires exonérés
A36: Déplacements | B36: Budget 36 mois, 45 | C36: 0.1 | D36: H | E36: H : transports à 10 %
A37: Autres charges (création de la société) | B37: Budget 36 mois, 49 | C37: 0 | D37: H | E37: H prudente : frais de greffe sans TVA
A38: Investissements | B38: Budget 36 mois, 56 et 57 | C38: 0.2 | D38: H | E38: H
A40: Mois par mois : onglet « Budget 36 mois », lignes 60 à 69 (36 mois). Les taux ci-dessus y sont repris (colonne AQ).

Sheet Prévu et réel
A1: Prévu et réel, mois par mois (année 1)
A2: Le prévu vient de « Budget 36 mois » (12 premiers mois) ; saisir le réel dès qu'il est connu, avec sa pièce.
A5: Indicateur | B5: Total 12 mois | C5: ='Budget 36 mois'!E5 -> 46327 | D5: ='Budget 36 mois'!F5 -> 46357 | E5: ='Budget 36 mois'!G5 -> 46388 | F5: ='Budget 36 mois'!H5 -> 46419 | G5: ='Budget 36 mois'!I5 -> 46447 | H5: ='Budget 36 mois'!J5 -> 46478 | I5: ='Budget 36 mois'!K5 -> 46508 | J5: ='Budget 36 mois'!L5 -> 46539 | ... N5: ='Budget 36 mois'!P5 -> 46661
A6: Nombre de soirées
A7: Prévu | B7: =SUM(C7:N7) -> 16 | C7: ='Budget 36 mois'!E13 -> 0 | D7: ='Budget 36 mois'!F13 -> 0 | E7: ='Budget 36 mois'!G13 -> 1 | F7: ='Budget 36 mois'!H13 -> 1 | G7: ='Budget 36 mois'!I13 -> 1 | H7: ='Budget 36 mois'!J13 -> 2 | I7: ='Budget 36 mois'!K13 -> 2 | J7: ='Budget 36 mois'!L13 -> 2 | ... N7: ='Budget 36 mois'!P13 -> 3
A8: Réel | B8: =SUM(C8:N8) -> 0
A9: Écart (réel − prévu) | B9: =SUM(C9:N9) -> 0 | C9: =IF(C8="",0,C8-C7) -> 0 | D9: =IF(D8="",0,D8-D7) -> 0 | E9: =IF(E8="",0,E8-E7) -> 0 | F9: =IF(F8="",0,F8-F7) -> 0 | G9: =IF(G8="",0,G8-G7) -> 0 | H9: =IF(H8="",0,H8-H7) -> 0 | I9: =IF(I8="",0,I8-I7) -> 0 | J9: =IF(J8="",0,J8-J7) -> 0 | ... N9: =IF(N8="",0,N8-N7) -> 0
A11: Chiffre d'affaires
A12: Prévu | B12: =SUM(C12:N12) -> 219642.86 | C12: ='Budget 36 mois'!E26 -> 0 | D12: ='Budget 36 mois'!F26 -> 0 | E12: ='Budget 36 mois'!G26 -> 10357.143 | F12: ='Budget 36 mois'!H26 -> 18482.143 | G12: ='Budget 36 mois'!I26 -> 13125 | H12: ='Budget 36 mois'!J26 -> 23750 | I12: ='Budget 36 mois'!K26 -> 31875 | J12: ='Budget 36 mois'!L26 -> 26517.857 | ... N12: ='Budget 36 mois'!P26 -> 39910.714
A13: Réel | B13: =SUM(C13:N13) -> 0
A14: Écart (réel − prévu) | B14: =SUM(C14:N14) -> 0 | C14: =IF(C13="",0,C13-C12) -> 0 | D14: =IF(D13="",0,D13-D12) -> 0 | E14: =IF(E13="",0,E13-E12) -> 0 | F14: =IF(F13="",0,F13-F12) -> 0 | G14: =IF(G13="",0,G13-G12) -> 0 | H14: =IF(H13="",0,H13-H12) -> 0 | I14: =IF(I13="",0,I13-I12) -> 0 | J14: =IF(J13="",0,J13-J12) -> 0 | ... N14: =IF(N13="",0,N13-N12) -> 0
A16: Total des frais généraux
A17: Prévu | B17: =SUM(C17:N17) -> 93529.857 | C17: ='Budget 36 mois'!E57 -> 2712 | D17: ='Budget 36 mois'!F57 -> 4660 | E17: ='Budget 36 mois'!G57 -> 2452.1429 | F17: ='Budget 36 mois'!H57 -> 7614.6429 | G17: ='Budget 36 mois'!I57 -> 34307.5 | H17: ='Budget 36 mois'!J57 -> 2520 | I17: ='Budget 36 mois'!K57 -> 1682.5 | J17: ='Budget 36 mois'!L57 -> 1575.3571 | ... N17: ='Budget 36 mois'!P57 -> 11843.214
A18: Réel | B18: =SUM(C18:N18) -> 0
A19: Écart (réel − prévu) | B19: =SUM(C19:N19) -> 0 | C19: =IF(C18="",0,C18-C17) -> 0 | D19: =IF(D18="",0,D18-D17) -> 0 | E19: =IF(E18="",0,E18-E17) -> 0 | F19: =IF(F18="",0,F18-F17) -> 0 | G19: =IF(G18="",0,G18-G17) -> 0 | H19: =IF(H18="",0,H18-H17) -> 0 | I19: =IF(I18="",0,I18-I17) -> 0 | J19: =IF(J18="",0,J18-J17) -> 0 | ... N19: =IF(N18="",0,N18-N17) -> 0
A21: Résultat d'exploitation
A22: Prévu | B22: =SUM(C22:N22) -> -36232.357 | C22: ='Budget 36 mois'!E59 -> -2712 | D22: ='Budget 36 mois'!F59 -> -4660 | E22: ='Budget 36 mois'!G59 -> -364.28571 | F22: ='Budget 36 mois'!H59 -> -4003.75 | G22: ='Budget 36 mois'!I59 -> -32093.75 | H22: ='Budget 36 mois'!J59 -> 4732.1429 | I22: ='Budget 36 mois'!K59 -> 6847.6786 | J22: ='Budget 36 mois'!L59 -> 5102.6786 | ... N22: ='Budget 36 mois'!P59 -> -700.89286
A23: Réel | B23: =SUM(C23:N23) -> 0
A24: Écart (réel − prévu) | B24: =SUM(C24:N24) -> 0 | C24: =IF(C23="",0,C23-C22) -> 0 | D24: =IF(D23="",0,D23-D22) -> 0 | E24: =IF(E23="",0,E23-E22) -> 0 | F24: =IF(F23="",0,F23-F22) -> 0 | G24: =IF(G23="",0,G23-G22) -> 0 | H24: =IF(H23="",0,H23-H22) -> 0 | I24: =IF(I23="",0,I23-I22) -> 0 | J24: =IF(J23="",0,J23-J22) -> 0 | ... N24: =IF(N23="",0,N23-N22) -> 0
A26: Pièces du réel
A27: Pièce justifiant le réel (comptabilité, relevé, factures)

Sheet Plan financier 3 ans
A1: Plan financier sur 3 ans
A2: Pop Tables · totaux annuels de « Budget 36 mois ». Exercice de novembre à octobre. Montants HT ; trésorerie TTC.
A5: Poste | B5: Unité | C5: Année 1 | D5: Année 2 | E5: Année 3 | F5: Nature et source
A6: Activité
A7: Villes actives (dès le début d'année) | B7: villes | C7: ='Budget 36 mois'!B7 -> 1 | D7: ='Budget 36 mois'!C7 -> 3 | E7: ='Budget 36 mois'!D7 -> 6 | F7: D-15 ; nouvelles villes ouvertes en novembre
A8: Soirées « place à l'unité » | B8: soirées | C8: ='Budget 36 mois'!B11 -> 9 | D8: ='Budget 36 mois'!C11 -> 33 | E8: ='Budget 36 mois'!D11 -> 66 | F8: D-15 : 1 par mois et par ville
A9: dont Premier soir | B9: soirées | C9: ='Budget 36 mois'!B8 -> 3 | D9: ='Budget 36 mois'!C8 -> 11 | E9: ='Budget 36 mois'!D8 -> 22
A10: dont Le Voyage | B10: soirées | C10: ='Budget 36 mois'!B9 -> 3 | D10: ='Budget 36 mois'!C9 -> 11 | E10: ='Budget 36 mois'!D9 -> 22
A11: dont La Grande Nuit | B11: soirées | C11: ='Budget 36 mois'!B10 -> 3 | D11: ='Budget 36 mois'!C10 -> 11 | E11: ='Budget 36 mois'!D10 -> 22
A12: Privatisations de salle | B12: soirées | C12: ='Budget 36 mois'!B12 -> 7 | D12: =3*40 -> 120 | E12: =6*40 -> 240 | F12: H en attendant les Ventes (D-16)
A13: Nombre total de soirées | B13: soirées | C13: ='Budget 36 mois'!B13 -> 16 | D13: ='Budget 36 mois'!C13 -> 153 | E13: ='Budget 36 mois'!D13 -> 306
A14: Compte de résultat simplifié
A15: Chiffre d'affaires | B15: € HT | C15: ='Budget 36 mois'!B26 -> 219642.86 | D15: ='Budget 36 mois'!C26 -> 2068750 | E15: ='Budget 36 mois'!D26 -> 4137500
A16: Coûts directs (y compris déplacements de production) | B16: € HT | C16: ='Budget 36 mois'!B30 -> 162345.36 | D16: ='Budget 36 mois'!C30 -> 1444293.2 | E16: ='Budget 36 mois'!D30 -> 2896286.4
A17: Marge sur coûts directs | B17: € HT | C17: ='Budget 36 mois'!B31 -> 57297.5 | D17: ='Budget 36 mois'!C31 -> 624456.79 | E17: ='Budget 36 mois'!D31 -> 1241213.6
A18: Taux de marge | B18: % du CA | C18: =IF(C15>0,C17/C15,0) -> 0.26086667 | D18: =IF(D15>0,D17/D15,0) -> 0.30185222 | E18: =IF(E15>0,E17/E15,0) -> 0.2999912
A19: Ressources humaines | B19: € HT | C19: ='Budget 36 mois'!B37 -> 0 | D19: ='Budget 36 mois'!C37 -> 97458.444 | E19: ='Budget 36 mois'!D37 -> 643836.89 | F19: Onglet Ressources humaines
A20: Marketing et communication courants | B20: € HT | C20: ='Budget 36 mois'!B41 -> 7200 | D20: ='Budget 36 mois'!C41 -> 15000 | E20: ='Budget 36 mois'!D41 -> 30000
A21: Lancement : campagne (10 000 €) et soirée de lancement | B21: € HT | C21: ='Budget 36 mois'!B42+'Budget 36 mois'!B43 -> 38000 | D21: ='Budget 36 mois'!C42+'Budget 36 mois'!C43 -> 0 | E21: ='Budget 36 mois'!D42+'Budget 36 mois'!D43 -> 0 | F21: Campagne fixée par le responsable Finance ; soirée D-14, montant H
A22: Ventes et prospection (hors salaire du commercial) | B22: € HT | C22: =SUM('Budget 36 mois'!B44:B47) -> 8065 | D22: =SUM('Budget 36 mois'!C44:C47) -> 17405 | E22: =SUM('Budget 36 mois'!D44:D47) -> 29210 | F22: Outils, rendez-vous, places offertes, supports et salons
A23: Protection juridique et assurance de la société (2 % du CA) | B23: € HT | C23: ='Budget 36 mois'!B48 -> 4392.8571 | D23: ='Budget 36 mois'!C48 -> 41375 | E23: ='Budget 36 mois'!D48 -> 82750
A24: Ouverture de villes | B24: € HT | C24: ='Budget 36 mois'!B52 -> 30000 | D24: ='Budget 36 mois'!C52 -> 45000 | E24: ='Budget 36 mois'!D52 -> 0
A25: Autres frais de fonctionnement | B25: € HT | C25: ='Budget 36 mois'!B56-C20-C21-C22-C23-C24 -> 5872 | D25: ='Budget 36 mois'!C56-D20-D21-D22-D23-D24 -> 20460 | E25: ='Budget 36 mois'!D56-E20-E21-E22-E23-E24 -> 76560 | F25: Locaux, logiciels, honoraires, banque, déplacements, licence, CFE, autres
A26: Total des frais généraux | B26: € HT | C26: ='Budget 36 mois'!B57 -> 93529.857 | D26: ='Budget 36 mois'!C57 -> 236698.44 | E26: ='Budget 36 mois'!D57 -> 862356.89
A27: Résultat d'exploitation | B27: € HT | C27: ='Budget 36 mois'!B59 -> -36232.357 | D27: ='Budget 36 mois'!C59 -> 387758.34 | E27: ='Budget 36 mois'!D59 -> 378856.68
A28: Investissements et besoin de financement
A29: Investissements (site D-19, identité, matériel) | B29: € HT | C29: ='Budget 36 mois'!B64 -> 18000 | D29: ='Budget 36 mois'!C64 -> 5000 | E29: ='Budget 36 mois'!D64 -> 10000
A30: Flux de l'année (résultat - investissements) | B30: € | C30: =C27-C29 -> -54232.357 | D30: =D27-D29 -> 382758.34 | E30: =E27-E29 -> 368856.68
A31: Flux cumulé | B31: € | C31: =C30 -> -54232.357 | D31: =C31+D30 -> 328525.98 | E31: =D31+E30 -> 697382.67
A32: Seuil de rentabilité | B32: soirées par an | C32: =IF(C17>0,C26/(C17/C13),0) -> 26.117679 | D32: =IF(D17>0,D26/(D17/D13),0) -> 57.994184 | E32: =IF(E17>0,E26/(E17/E13),0) -> 212.59936 | F32: Frais généraux ÷ marge moyenne par soirée
A34: Trésorerie et besoin de financement
A35: Besoin de financement : point bas du flux cumulé (hors apport, TVA et pré-vente) | B35: € | C35: =MAX(0,-MIN(C31:E31)) -> 54232.357
A36: Trésorerie : point bas sur 36 mois (apport de 7 000 €, TVA et pré-vente compris, avant levée) | B36: € | C36: =MIN('Budget 36 mois'!E80:AN80) -> 10071.107
A37: Mois du point bas | C37: =INDEX('Budget 36 mois'!E5:AN5,MATCH(C36,'Budget 36 mois'!E80:AN80,0)) -> 46447
A38: Trésorerie en fin d'année (avant levée) | B38: € | C38: ='Budget 36 mois'!P80 -> 54448.821 | D38: ='Budget 36 mois'!AB80 -> 496353.5 | E38: ='Budget 36 mois'!AN80 -> 871460.36
A39: Crédit de TVA en fin d'année | B39: € | C39: ='Budget 36 mois'!B73 -> 8318.8214 | D39: ='Budget 36 mois'!C73 -> 0 | E39: ='Budget 36 mois'!D73 -> 0
A41: Le dimensionnement de la levée (contingence, trésorerie de sécurité) se trouve dans 2 FINANCE/FINANCEMENT, note pour décision du 28/10/2026 (soir). Le financement se suit dans le modèle Financement.

Sheet Ressources humaines
A1: Ressources humaines sur 36 mois
