Workbook

Sheet Mode d'emploi
A1: Simulation complète du Pilote 1 — « Premier soir »
A2: 28/10/2026 · 6 OPERATIONS/PRODUCTION · Document de travail du pôle Opérations : propositions et hypothèses, rien n'est décidé (voir REGISTRE DES DECISIONS).
A4: À quoi elle sert
A5: Chiffrer une soirée de bout en bout — recettes, chaque poste de coût, personnel, matériel, temps des fondateurs — et voir ce que change le passage de 24 à 30 ou 35 couverts, puis le passage du pilote (fondateurs présents) au régime récurrent (un assistant de production). C'est le livrable « simulation complète d'une réservation » du plan de travail (action 19) et la réponse à la question de la Finance « combien coûte une réservation complète ? ».
A7: Onglets
A8: « Hypothèses » : toutes les valeurs d'entrée (cellules jaunes), chacune avec sa nature et sa source. « Simulation » : quatre configurations côte à côte, tout est calculé. « Déroulé J » : qui fait quoi, heure par heure, le jour de la soirée.
A10: Lecture
A11: Nature des valeurs (voir RULES) : F = fait sourcé · P = proposition · H = hypothèse à remplacer par un devis. Les montants sont HT sauf mention TTC. La plupart des coûts reprennent les hypothèses de la Finance (modèle Prévisions, 27-28/10/2026) pour rester comparables ; les écarts sont signalés.
A12: Codes couleur : texte bleu sur fond jaune = saisie · noir = calcul · vert = lien vers un autre onglet · fond rouge = règle non respectée (plafond matières, coefficient vin, marge négative).
A13: Limite importante : la location de vaisselle (Options) n'est pas chiffrée faute de tarif public ; le nombre de pièces à louer est calculé pour la demande de devis. Tant que le prix unitaire reste à 0, le coût total est sous-estimé.

Sheet Simulation
A1: Simulation d'une soirée « Premier soir »
A2: Une colonne par configuration. Saisir uniquement les lignes 5 à 7 (jaune). Montants HT.
A4: Configuration | C4: Pilote 1 — 24 couverts | D4: Récurrent — 24 couverts | E4: Récurrent — 30 couverts | F4: Récurrent — 35 couverts
A5: Couverts | C5: 24 | D5: 24 | E5: 30 | F5: 35
A6: Criticité (C1, C2, C3) | C6: C2 | D6: C1 | E6: C1 | F6: C1
A7: Régime (Pilote / Récurrent) | C7: Pilote | D7: Récurrent | E7: Récurrent | F7: Récurrent
A9: 1. Recettes
A10: Convives payants | C10: =ROUND(C5*Hypothèses!$B$8,0) -> 19 | D10: =ROUND(D5*Hypothèses!$B$8,0) -> 19 | E10: =ROUND(E5*Hypothèses!$B$8,0) -> 24 | F10: =ROUND(F5*Hypothèses!$B$8,0) -> 28
A11: Prix HT par convive | C11: =Hypothèses!$B$6/(1+Hypothèses!$B$7) -> 258.92857 | D11: =Hypothèses!$B$6/(1+Hypothèses!$B$7) -> 258.92857 | E11: =Hypothèses!$B$6/(1+Hypothèses!$B$7) -> 258.92857 | F11: =Hypothèses!$B$6/(1+Hypothèses!$B$7) -> 258.92857
A12: Chiffre d'affaires HT | C12: =C10*C11 -> 4919.6429 | D12: =D10*D11 -> 4919.6429 | E12: =E10*E11 -> 6214.2857 | F12: =F10*F11 -> 7250
A13: dont part menu | C13: =C12*Hypothèses!$B$9 -> 3443.75 | D13: =D12*Hypothèses!$B$9 -> 3443.75 | E13: =E12*Hypothèses!$B$9 -> 4350 | F13: =F12*Hypothèses!$B$9 -> 5075
A14: dont part accords | C14: =C12*(1-Hypothèses!$B$9) -> 1475.8929 | D14: =D12*(1-Hypothèses!$B$9) -> 1475.8929 | E14: =E12*(1-Hypothèses!$B$9) -> 1864.2857 | F14: =F12*(1-Hypothèses!$B$9) -> 2175
A15: 2. Personnel (effectifs)
A16: Brigade (second, commis) | C16: =ROUNDUP(C5/Hypothèses!$B$26,0) -> 3 | D16: =ROUNDUP(D5/Hypothèses!$B$26,0) -> 3 | E16: =ROUNDUP(E5/Hypothèses!$B$26,0) -> 3 | F16: =ROUNDUP(F5/Hypothèses!$B$26,0) -> 4
A17: Maître d'hôtel | C17: =(C5>=9)*1+(C5>=41)*1 -> 1 | D17: =(D5>=9)*1+(D5>=41)*1 -> 1 | E17: =(E5>=9)*1+(E5>=41)*1 -> 1 | F17: =(F5>=9)*1+(F5>=41)*1 -> 1
A18: Serveurs | C18: =ROUNDUP(C5/Hypothèses!$B$25,0) -> 4 | D18: =ROUNDUP(D5/Hypothèses!$B$25,0) -> 4 | E18: =ROUNDUP(E5/Hypothèses!$B$25,0) -> 5 | F18: =ROUNDUP(F5/Hypothèses!$B$25,0) -> 5
A19: Serveur de réserve | C19: =IF(C6="C1",0,1) -> 1 | D19: =IF(D6="C1",0,1) -> 0 | E19: =IF(E6="C1",0,1) -> 0 | F19: =IF(F6="C1",0,1) -> 0
A20: Sommelier invité | C20: =1 -> 1 | D20: =1 -> 1 | E20: =1 -> 1 | F20: =1 -> 1
A21: Aide sommelier | C21: =(C5>=20)*1+(C5>=41)*1 -> 1 | D21: =(D5>=20)*1+(D5>=41)*1 -> 1 | E21: =(E5>=20)*1+(E5>=41)*1 -> 1 | F21: =(F5>=20)*1+(F5>=41)*1 -> 1
A22: Plongeurs | C22: =1+(C5>=17)*1+(C5>=41)*1 -> 2 | D22: =1+(D5>=17)*1+(D5>=41)*1 -> 2 | E22: =1+(E5>=17)*1+(E5>=41)*1 -> 2 | F22: =1+(F5>=17)*1+(F5>=41)*1 -> 2
A23: Production : fondateurs (pilote) ou assistant (récurrent) | B23: Pilote : responsable de production + interlocuteur client | C23: =IF(C7="Pilote",2,1) -> 2 | D23: =IF(D7="Pilote",2,1) -> 1 | E23: =IF(E7="Pilote",2,1) -> 1 | F23: =IF(F7="Pilote",2,1) -> 1
A24: Total, hors chef | C24: =SUM(C16:C23) -> 15 | D24: =SUM(D16:D23) -> 13 | E24: =SUM(E16:E23) -> 14 | F24: =SUM(F16:F23) -> 15
A25: 3. Coûts de la soirée
A26: Lieu | C26: =Hypothèses!$B$21 -> 1500 | D26: =Hypothèses!$B$21 -> 1500 | E26: =Hypothèses!$B$21 -> 1500 | F26: =Hypothèses!$B$21 -> 1500
A27: Chef (cachet et défraiement) | C27: =Hypothèses!$B$22 -> 950 | D27: =Hypothèses!$B$22 -> 950 | E27: =Hypothèses!$B$22 -> 950 | F27: =Hypothèses!$B$22 -> 950
A28: Matières du menu | C28: =C10*Hypothèses!$B$14 -> 1045 | D28: =D10*Hypothèses!$B$14 -> 1045 | E28: =E10*Hypothèses!$B$14 -> 1320 | F28: =F10*Hypothèses!$B$14 -> 1540
A29: Vins et jus d'accord | C29: =C10*Hypothèses!$B$16 -> 570 | D29: =D10*Hypothèses!$B$16 -> 570 | E29: =E10*Hypothèses!$B$16 -> 720 | F29: =F10*Hypothèses!$B$16 -> 840
A30: Équipe payée (brigade, salle, sommellerie, plonge) | C30: =C16*Hypothèses!$B$27*Hypothèses!$B$28+C17*Hypothèses!$B$29*Hypothèses!$B$30+(C18+C19)*Hypothèses!$B$31*Hypothèses!$B$32+C20*Hypothèses!$B$31*Hypothèses!$B$33+C21*Hypothèses!$B$31*Hypothèses!$B$34+C22*Hypothèses!$B$31*Hypothèses!$B$35 -> 3846 | D30: =D16*Hypothèses!$B$27*Hypothèses!$B$28+D17*Hypothèses!$B$29*Hypothèses!$B$30+(D18+D19)*Hypothèses!$B$31*Hypothèses!$B$32+D20*Hypothèses!$B$31*Hypothèses!$B$33+D21*Hypothèses!$B$31*Hypothèses!$B$34+D22*Hypothèses!$B$31*Hypothèses!$B$35 -> 3601 | E30: =E16*Hypothèses!$B$27*Hypothèses!$B$28+E17*Hypothèses!$B$29*Hypothèses!$B$30+(E18+E19)*Hypothèses!$B$31*Hypothèses!$B$32+E20*Hypothèses!$B$31*Hypothèses!$B$33+E21*Hypothèses!$B$31*Hypothèses!$B$34+E22*Hypothèses!$B$31*Hypothèses!$B$35 -> 3846 | F30: =F16*Hypothèses!$B$27*Hypothèses!$B$28+F17*Hypothèses!$B$29*Hypothèses!$B$30+(F18+F19)*Hypothèses!$B$31*Hypothèses!$B$32+F20*Hypothèses!$B$31*Hypothèses!$B$33+F21*Hypothèses!$B$31*Hypothèses!$B$34+F22*Hypothèses!$B$31*Hypothèses!$B$35 -> 4231
A31: Assistant de production (récurrent) | B31: Pilote : fondateurs non rémunérés | C31: =IF(C7="Pilote",0,(Hypothèses!$B$36+Hypothèses!$B$37)*Hypothèses!$B$38) -> 0 | D31: =IF(D7="Pilote",0,(Hypothèses!$B$36+Hypothèses!$B$37)*Hypothèses!$B$38) -> 1120 | E31: =IF(E7="Pilote",0,(Hypothèses!$B$36+Hypothèses!$B$37)*Hypothèses!$B$38) -> 1120 | F31: =IF(F7="Pilote",0,(Hypothèses!$B$36+Hypothèses!$B$37)*Hypothèses!$B$38) -> 1120
A32: Labo | C32: =Hypothèses!$B$23 -> 0 | D32: =Hypothèses!$B$23 -> 0 | E32: =Hypothèses!$B$23 -> 0 | F32: =Hypothèses!$B$23 -> 0
A33: Location de vaisselle (Options) | B33: Non chiffrée tant que le prix par pièce est à 0 | C33: =C5*(Hypothèses!$B$17+Hypothèses!$B$18+1+Hypothèses!$B$17*Hypothèses!$B$43)*Hypothèses!$B$41+Hypothèses!$B$42 -> 0 | D33: =D5*(Hypothèses!$B$17+Hypothèses!$B$18+1+Hypothèses!$B$17*Hypothèses!$B$43)*Hypothèses!$B$41+Hypothèses!$B$42 -> 0 | E33: =E5*(Hypothèses!$B$17+Hypothèses!$B$18+1+Hypothèses!$B$17*Hypothèses!$B$43)*Hypothèses!$B$41+Hypothèses!$B$42 -> 0 | F33: =F5*(Hypothèses!$B$17+Hypothèses!$B$18+1+Hypothèses!$B$17*Hypothèses!$B$43)*Hypothèses!$B$41+Hypothèses!$B$42 -> 0
A34: Ménage, assurance, décor, photographe | C34: =Hypothèses!$B$45+Hypothèses!$B$46+Hypothèses!$B$47+Hypothèses!$B$48 -> 760 | D34: =Hypothèses!$B$45+Hypothèses!$B$46+Hypothèses!$B$47+Hypothèses!$B$48 -> 760 | E34: =Hypothèses!$B$45+Hypothèses!$B$46+Hypothèses!$B$47+Hypothèses!$B$48 -> 760 | F34: =Hypothèses!$B$45+Hypothèses!$B$46+Hypothèses!$B$47+Hypothèses!$B$48 -> 760
A35: Frais de paiement et commission | C35: =C12*(Hypothèses!$B$10+Hypothèses!$B$11) -> 324.69643 | D35: =D12*(Hypothèses!$B$10+Hypothèses!$B$11) -> 324.69643 | E35: =E12*(Hypothèses!$B$10+Hypothèses!$B$11) -> 410.14286 | F35: =F12*(Hypothèses!$B$10+Hypothèses!$B$11) -> 478.5
A36: Total des coûts | C36: =SUM(C26:C35) -> 8995.6964 | D36: =SUM(D26:D35) -> 9870.6964 | E36: =SUM(E26:E35) -> 10626.143 | F36: =SUM(F26:F35) -> 11419.5
A37: 4. Résultat
A38: Marge de la soirée | C38: =C12-C36 -> -4076.0536 | D38: =D12-D36 -> -4951.0536 | E38: =E12-E36 -> -4411.8571 | F38: =F12-F36 -> -4169.5
A39: Taux de marge | C39: =IF(C12>0,C38/C12,0) -> -0.82852632 | D39: =IF(D12>0,D38/D12,0) -> -1.0063848 | E39: =IF(E12>0,E38/E12,0) -> -0.70995402 | F39: =IF(F12>0,F38/F12,0) -> -0.57510345
A40: Personnel payé (équipe + assistant) en % du CA | C40: =(C30+C31)/C12 -> 0.78176407 | D40: =(D30+D31)/D12 -> 0.9596225 | E40: =(E30+E31)/E12 -> 0.79912644 | F40: =(F30+F31)/F12 -> 0.73806897
A41: Prix plancher TTC par convive (marge nulle) | C41: =((SUM(C26:C34)-C28-C29)/(1-Hypothèses!$B$10-Hypothèses!$B$11)+C10*(Hypothèses!$B$14+Hypothèses!$B$16)/(1-Hypothèses!$B$10-Hypothèses!$B$11))/C10*(1+Hypothèses!$B$7) -> 547.25121 | D41: =((SUM(D26:D34)-D28-D29)/(1-Hypothèses!$B$10-Hypothèses!$B$11)+D10*(Hypothèses!$B$14+Hypothèses!$B$16)/(1-Hypothèses!$B$10-Hypothèses!$B$11))/D10*(1+Hypothèses!$B$7) -> 602.47492 | E41: =((SUM(E26:E34)-E28-E29)/(1-Hypothèses!$B$10-Hypothèses!$B$11)+E10*(Hypothèses!$B$14+Hypothèses!$B$16)/(1-Hypothèses!$B$10-Hypothèses!$B$11))/E10*(1+Hypothèses!$B$7) -> 510.4354 | F41: =((SUM(F26:F34)-F28-F29)/(1-Hypothèses!$B$10-Hypothèses!$B$11)+F10*(Hypothèses!$B$14+Hypothèses!$B$16)/(1-Hypothèses!$B$10-Hypothèses!$B$11))/F10*(1+Hypothèses!$B$7) -> 468.56531
A42: Remplissage d'équilibre au prix affiché | B42: Au-delà de 100 % : impossible au prix affiché | C42: =IF(C11*(1-Hypothèses!$B$10-Hypothèses!$B$11)-Hypothèses!$B$14-Hypothèses!$B$16>0,(SUM(C26:C34)-C28-C29)/(C11*(1-Hypothèses!$B$10-Hypothèses!$B$11)-Hypothèses!$B$14-Hypothèses!$B$16)/C5,0) -> 1.8745303 | D42: =IF(D11*(1-Hypothèses!$B$10-Hypothèses!$B$11)-Hypothèses!$B$14-Hypothèses!$B$16>0,(SUM(D26:D34)-D28-D29)/(D11*(1-Hypothèses!$B$10-Hypothèses!$B$11)-Hypothèses!$B$14-Hypothèses!$B$16)/D5,0) -> 2.106987 | E42: =IF(E11*(1-Hypothèses!$B$10-Hypothèses!$B$11)-Hypothèses!$B$14-Hypothèses!$B$16>0,(SUM(E26:E34)-E28-E29)/(E11*(1-Hypothèses!$B$10-Hypothèses!$B$11)-Hypothèses!$B$14-Hypothèses!$B$16)/E5,0) -> 1.7376599 | F42: =IF(F11*(1-Hypothèses!$B$10-Hypothèses!$B$11)-Hypothèses!$B$14-Hypothèses!$B$16>0,(SUM(F26:F34)-F28-F29)/(F11*(1-Hypothèses!$B$10-Hypothèses!$B$11)-Hypothèses!$B$14-Hypothèses!$B$16)/F5,0) -> 1.5595582
...

Sheet Hypothèses
A1: Hypothèses de la simulation
A2: Cellules jaunes modifiables. Fin = modèle Prévisions de la Finance (2 FINANCE/PREVISIONS), onglets « Prix et marges » et « Staffing ».
A4: Paramètre | B4: Valeur | C4: Unité | D4: Nature | E4: Source / justification
A5: Prix et recettes
A6: Prix affiché par convive | B6: 290 | C6: € TTC | D6: P | E6: 5 PRODUIT/Fou d'un soir le pricing.md : « Premier soir » 290 €
A7: Taux de TVA moyen | B7: 0.12 | C7: % | D7: H | E7: Fin, Prix et marges ligne 12 (taux mixte restauration et alcool, à faire confirmer par un expert-comptable)
A8: Taux de remplissage | B8: 0.8 | C8: % des couverts | D8: H | E8: Fin, ligne 8
A9: Part du prix HT affectée au menu (le reste : accords) | B9: 0.7 | C9: % | D9: H | E9: Hypothèse des Opérations pour appliquer séparément le plafond matières et le coefficient vin ; à valider avec le Produit
A10: Frais de paiement | B10: 0.016 | C10: % du CA | D10: H | E10: Fin, ligne 30
A11: Commission d'apporteur (concierges) | B11: 0.05 | C11: % du CA | D11: H | E11: Fin, ligne 31 (Premier soir)
A12: Matières et vins
A13: Plafond du coût matières du menu | B13: 0.35 | C13: % du prix HT du menu | D13: P | E13: Responsable Opérations, 28/10/2026 : « rester en dessous de 35 % grand max ». Produits d'exception compris
A14: Coût matières estimé par convive | B14: 55 | C14: € HT | D14: H | E14: Fin, ligne 23 ; à remplacer par le coût réel du menu du chef
A15: Coefficient minimum sur les vins (prix de vente / coût) | B15: 4 | C15: × | D15: P | E15: Responsable Opérations, 28/10/2026 : « x4 minimum » ; un coefficient de 4 équivaut à un coût de 25 % du prix
A16: Coût des vins et jus d'accord estimé par convive | B16: 30 | C16: € HT | D16: H | E16: Fin, ligne 24 ; à remplacer par les prix du catalogue du partenaire vin (AdVini)
A17: Nombre de services (plats) | B17: 6 | C17: plats | D17: P | E17: Offre du Produit : « Premier soir », 6 services
A18: Nombre d'accords (verres) par convive | B18: 4 | C18: verres | D18: P | E18: Offre du Produit : 4 accords
A19: Volume servi par accord | B19: 10 | C19: cl | D19: H | E19: Usage courant, à confirmer avec le sommelier
A20: Lieu, chef, labo
A21: Mise à disposition du lieu | B21: 1500 | C21: € HT | D21: H | E21: Fin, ligne 19 (à confirmer par les Ventes, donnée n° 1)
A22: Chef : cachet et forfait de défraiement | B22: 950 | C22: € HT | D22: H | E22: Fin, ligne 20. Orientation du 28/10 : forfait de défraiement plafonné selon le niveau du chef, pas un remboursement intégral ; barème à définir avec la Finance
A23: Labo de production | B23: 0 | C23: € HT | D23: P | E23: Orientation du 28/10 : pas de labo pour les soirées foodies (réservé aux événements privés et B2B) ; mise en place dans la cuisine du lieu le jour J
A24: Personnel (règles du calculateur de staffing, heures et taux de la Finance)
A25: Couverts par serveur | B25: 7 | C25: couverts | D25: P | E25: Calculateur de staffing (Opérations)
A26: Couverts par membre de brigade | B26: 10 | C26: couverts | D26: P | E26: Calculateur de staffing
A27: Heures : brigade | B27: 11 | C27: h | D27: P | E27: Fin retient 9 h ; porté à 11 h car, sans labo, la mise en place se fait sur place le jour J (déroulé PR-07 : arrivée vers 14 h, fin vers 1 h)
A28: Coût horaire : brigade | B28: 35 | C28: €/h | D28: H | E28: Fin, Staffing
A29: Heures : maître d'hôtel | B29: 8 | C29: h | D29: H | E29: Fin, Staffing
A30: Coût horaire : maître d'hôtel | B30: 45 | C30: €/h | D30: H | E30: Fin, Staffing
A31: Heures : serveurs, sommellerie, plonge | B31: 7 | C31: h | D31: H | E31: Fin, Staffing
A32: Coût horaire : serveur | B32: 35 | C32: €/h | D32: H | E32: Fin, Staffing
A33: Coût horaire : sommelier invité | B33: 60 | C33: €/h | D33: H | E33: Fin, Staffing
A34: Coût horaire : aide sommelier | B34: 38 | C34: €/h | D34: H | E34: Fin, Staffing
A35: Coût horaire : plonge | B35: 30 | C35: €/h | D35: H | E35: Fin, Staffing
A36: Assistant de production (régime récurrent) : heures le jour J | B36: 12 | C36: h | D36: H | E36: Orientation du 28/10 : après les pilotes, un seul assistant de production ; présent de l'arrivée de la brigade à la restitution du lieu
... A39: Fondateurs au pilote : heures par personne (préparation et jour J) | B39: 40 | C39: h | D39: H | E39: Pilote : responsable de production et interlocuteur client, non rémunérés (Fin) ; heures à mesurer
A40: Location de matériel (Options)
A41: Prix de location par pièce (assiette, verre, couvert) | B41: 0 | C41: € HT | D41: H | E41: Aucun tarif public (catalogues Options : gammes Standard à Excellence, sans prix). À obtenir par devis
A42: Forfait livraison et reprise | B42: 0 | C42: € HT | D42: H | E42: À obtenir par devis ; livraison et reprise un jour de fermeture
A43: Couverts (fourchette, couteau, cuillère) par service | B43: 2 | C43: pièces | D43: H | E43: Moyenne, à préciser avec le chef
...

Sheet Déroulé J
A1: Déroulé du jour J — dîner à 20 h, mise en place sur place (sans labo)
A2: Trame PR-07 (fiches process), précisée pour une soirée foodies. Horaires indicatifs (P), à ajuster avec le chef.
A4: Heure | B4: Étape | C4: Responsable | D4: Présents
A5: 9 h 00 | B5: Ouverture du lieu, état des lieux d'entrée photographié, réception des produits frais (contrôle des températures) | C5: Production (fondateur ou assistant) | D5: Production
A6: 10 h 00 | B6: Livraison et contrôle du matériel loué (Options) ; mise en froid des vins et jus | C6: Production | D6: Production
A7: 14 h 00 | B7: Arrivée du chef et de la brigade ; mise en place sur place, dans la cuisine du lieu | C7: Chef | D7: Chef, brigade, production
A8: 17 h 00 | B8: Arrivée de la plonge ; premier lavage des ustensiles de mise en place | C8: Production | D8: + plonge
A9: 18 h 00 | B9: Arrivée de la salle et de la sommellerie ; dressage des tables ; fiches des vins apprises (éléments de langage du partenaire vin) | C9: Maître d'hôtel, sommelier invité | D9: + salle, sommellerie
A10: 19 h 00 | B10: Briefing de toute l'équipe : menu, accords, allergies par table, consignes sur l'alcool | C10: Production, chef, maître d'hôtel | D10: Toute l'équipe
A11: 19 h 30 | B11: Accueil prêt, vestiaire ouvert | C11: Maître d'hôtel | D11: Toute l'équipe
A12: 20 h 00 | B12: Arrivée des invités ; apéritif | C12: Maître d'hôtel | D12: Toute l'équipe
A13: 20 h 30 | B13: Passage à table ; le chef présente son menu | C13: Chef | D13: Toute l'équipe
A14: 20 h 30 à 23 h 00 | B14: Service des 6 plats et des 4 accords ; la cuisine du lieu sert surtout à l'envoi | C14: Chef, maître d'hôtel, sommelier | D14: Toute l'équipe
A15: 23 h 00 | B15: Dessert ; le chef passe en salle | C15: Chef | D15: Toute l'équipe
... A19: Lendemain | B19: Reprise du matériel loué ; questionnaire de satisfaction envoyé ; retours du chef et du lieu | C19: Production | D19: Production
