Workbook

Sheet Mode d'emploi
A1: Calculateur de staffing par événement — Fou d'un soir
A2: 28/10/2026 · 6 OPERATIONS/PRODUCTION · Document de travail du pôle Opérations : propositions, rien n'est décidé (voir REGISTRE DES DECISIONS).
A4: À quoi il sert
A5: Pour chaque événement, il calcule la classe de taille (T1 à T5), la catégorie (taille / criticité), le délai minimum de préparation, la charge de plonge, l'équipe nécessaire rôle par rôle, les process à appliquer et, une fois les heures et les taux renseignés, le coût de personnel à transmettre à la Finance (donnée n° 5).
A6: Il applique la note « 2026 1028 Typologie des événements, process et staffing » (même dossier).
A8: Comment s'en servir
A9: 1. Onglet « Calculateur » : une colonne par événement. Ne remplir que les cellules jaunes à texte bleu (lignes 5 à 13). Tout le reste se calcule.
A10: 2. Criticité : C1 Standard, C2 Premium, C3 Signature (définitions dans l'onglet « Paramètres »).
A11: 3. « Service de salle fourni par » : choisir « Restaurant » si l'équipe du restaurant hôte assure la salle. Les postes de salle sont alors comptés à part et sortis du coût.
A12: 4. Onglet « Paramètres » : les ratios et les seuils sont modifiables (cellules jaunes). Renseigner les heures par personne et les coûts horaires dès qu'un devis est reçu : le coût de personnel apparaît alors dans le calculateur.
A14: Codes couleur
A15: Texte bleu sur fond jaune = valeur à saisir ou hypothèse modifiable · texte noir = calcul · texte vert = lien vers un autre onglet.
... A20: Les événements de plus de 60 couverts (T5 : mariages, grands événements) sont hors périmètre à ce stade : le calculateur les signale sans les chiffrer de façon fiable.

Sheet Calculateur
A1: Calculateur de staffing — une colonne par événement
A2: Ne saisir que les cellules jaunes (lignes 5 à 13). Exemples : formats de l'offre du Produit et de la soirée de lancement du Marketing (propositions, non décidées).
A4: Saisie | B4: Unité / choix
A5: Nom de l'événement | B5: texte | C5: Pilote 1 — Premier soir | D5: Pilote 2 — La Grande Nuit | E5: Le Voyage | F5: Lancement — option 2 (Lapérouse) | G5: Tête-à-tête | H5: Table d'affaires
A6: Format | B6: texte | C6: Offre A | D6: Offre A | E6: Offre A | F6: Lancement presse | G6: Offre B | H6: Offre B
A7: Couverts | B7: nombre | C7: 24 | D7: 20 | E7: 24 | F7: 30 | G7: 2 | H7: 10
A8: Services (plats) | B8: nombre | C8: 6 | D8: 9 | E8: 7
A9: Accords (verres par convive, hors eau) | B9: nombre | C9: 4
A10: Criticité | B10: C1 / C2 / C3 | C10: C2 | D10: C2 | E10: C2 | F10: C3 | G10: C2 | H10: C2
A11: Nombre de salons | B11: nombre | C11: 1 | D11: 1 | E11: 1 | F11: 3 | G11: 1 | H11: 1
A12: Logistique d'accès particulière | B12: Oui / Non | C12: Non | D12: Non | E12: Non | F12: Non | G12: Non | H12: Non
A13: Service de salle fourni par | B13: Nous / Restaurant | C13: Nous | D13: Nous | E13: Nous | F13: Nous | G13: Nous | H13: Nous
A15: Résultats
A16: Classe de taille | C16: =IF(C7="","",INDEX(Paramètres!$A$19:$A$23,MATCH(TRUE(),INDEX(Paramètres!$B$19:$B$23>=C7,0),0))) -> T3 | D16: =IF(D7="","",INDEX(Paramètres!$A$19:$A$23,MATCH(TRUE(),INDEX(Paramètres!$B$19:$B$23>=D7,0),0))) -> T3 | E16: =IF(E7="","",INDEX(Paramètres!$A$19:$A$23,MATCH(TRUE(),INDEX(Paramètres!$B$19:$B$23>=E7,0),0))) -> T3 | F16: =IF(F7="","",INDEX(Paramètres!$A$19:$A$23,MATCH(TRUE(),INDEX(Paramètres!$B$19:$B$23>=F7,0),0))) -> T3 | G16: =IF(G7="","",INDEX(Paramètres!$A$19:$A$23,MATCH(TRUE(),INDEX(Paramètres!$B$19:$B$23>=G7,0),0))) -> T1 | H16: =IF(H7="","",INDEX(Paramètres!$A$19:$A$23,MATCH(TRUE(),INDEX(Paramètres!$B$19:$B$23>=H7,0),0))) -> T2 | I16: =IF(I7="","",INDEX(Paramètres!$A$19:$A$23,MATCH(TRUE(),INDEX(Paramètres!$B$19:$B$23>=I7,0),0)))
A17: Catégorie (taille / criticité) | C17: =IF(OR(C7="",C10=""),"",C16&" / "&C10) -> T3 / C2 | D17: =IF(OR(D7="",D10=""),"",D16&" / "&D10) -> T3 / C2 | E17: =IF(OR(E7="",E10=""),"",E16&" / "&E10) -> T3 / C2 | F17: =IF(OR(F7="",F10=""),"",F16&" / "&F10) -> T3 / C3 | G17: =IF(OR(G7="",G10=""),"",G16&" / "&G10) -> T1 / C2 | H17: =IF(OR(H7="",H10=""),"",H16&" / "&H10) -> T2 / C2 | I17: =IF(OR(I7="",I10=""),"",I16&" / "&I10)
A18: Dans le périmètre ? | C18: =IF(C16="","",INDEX(Paramètres!$D$19:$D$23,MATCH(C16,Paramètres!$A$19:$A$23,0))) -> Oui : cœur de l'offre | D18: =IF(D16="","",INDEX(Paramètres!$D$19:$D$23,MATCH(D16,Paramètres!$A$19:$A$23,0))) -> Oui : cœur de l'offre | E18: =IF(E16="","",INDEX(Paramètres!$D$19:$D$23,MATCH(E16,Paramètres!$A$19:$A$23,0))) -> Oui : cœur de l'offre | F18: =IF(F16="","",INDEX(Paramètres!$D$19:$D$23,MATCH(F16,Paramètres!$A$19:$A$23,0))) -> Oui : cœur de l'offre | G18: =IF(G16="","",INDEX(Paramètres!$D$19:$D$23,MATCH(G16,Paramètres!$A$19:$A$23,0))) -> Oui | H18: =IF(H16="","",INDEX(Paramètres!$D$19:$D$23,MATCH(H16,Paramètres!$A$19:$A$23,0))) -> Oui | I18: =IF(I16="","",INDEX(Paramètres!$D$19:$D$23,MATCH(I16,Paramètres!$A$19:$A$23,0)))
A19: Délai minimum de préparation (semaines) | C19: =IF(C10="","",INDEX(Paramètres!$B$28:$B$30,MATCH(C10,Paramètres!$A$28:$A$30,0))) -> 8 | D19: =IF(D10="","",INDEX(Paramètres!$B$28:$B$30,MATCH(D10,Paramètres!$A$28:$A$30,0))) -> 8 | E19: =IF(E10="","",INDEX(Paramètres!$B$28:$B$30,MATCH(E10,Paramètres!$A$28:$A$30,0))) -> 8 | F19: =IF(F10="","",INDEX(Paramètres!$B$28:$B$30,MATCH(F10,Paramètres!$A$28:$A$30,0))) -> 10 | G19: =IF(G10="","",INDEX(Paramètres!$B$28:$B$30,MATCH(G10,Paramètres!$A$28:$A$30,0))) -> 8 | H19: =IF(H10="","",INDEX(Paramètres!$B$28:$B$30,MATCH(H10,Paramètres!$A$28:$A$30,0))) -> 8 | I19: =IF(I10="","",INDEX(Paramètres!$B$28:$B$30,MATCH(I10,Paramètres!$A$28:$A$30,0)))
A20: Assiettes à laver (couverts × services) | B20: hors pain, mises en bouche, couverts | C20: =IF(OR(C7="",C8=""),"",C7*C8) -> 144 | D20: =IF(OR(D7="",D8=""),"",D7*D8) -> 180 | E20: =IF(OR(E7="",E8=""),"",E7*E8) -> 168 | F20: =IF(OR(F7="",F8=""),"",F7*F8) | G20: =IF(OR(G7="",G8=""),"",G7*G8) | H20: =IF(OR(H7="",H8=""),"",H7*H8) | I20: =IF(OR(I7="",I8=""),"",I7*I8)
A21: Verres à laver (couverts × (accords + eau)) | B21: si accords vides : eau seule | C21: =IF(C7="","",C7*(N(C9)+1)) -> 120 | D21: =IF(D7="","",D7*(N(D9)+1)) -> 20 | E21: =IF(E7="","",E7*(N(E9)+1)) -> 24 | F21: =IF(F7="","",F7*(N(F9)+1)) -> 30 | G21: =IF(G7="","",G7*(N(G9)+1)) -> 2 | H21: =IF(H7="","",H7*(N(H9)+1)) -> 10 | I21: =IF(I7="","",I7*(N(I9)+1))
A23: Équipe nécessaire (personnes) | B23: Règle
A24: =Paramètres!A34 -> Chef invité | B24: =Paramètres!E34 -> 1 par événement. Son cachet n'est pas horaire : le saisir à part avec la Finance (donnée n° 2). | C24: =IF(C$7="","",1) -> 1 | D24: =IF(D$7="","",1) -> 1 | E24: =IF(E$7="","",1) -> 1 | F24: =IF(F$7="","",1) -> 1 | G24: =IF(G$7="","",1) -> 1 | H24: =IF(H$7="","",1) -> 1 | I24: =IF(I$7="","",1)
A25: =Paramètres!A35 -> Brigade (second, commis) | B25: =Paramètres!E35 -> Couverts ÷ couverts par membre de brigade, arrondi au supérieur. | C25: =IF(C$7="","",ROUNDUP(C$7/Paramètres!$B$6,0)) -> 3 | D25: =IF(D$7="","",ROUNDUP(D$7/Paramètres!$B$6,0)) -> 2 | E25: =IF(E$7="","",ROUNDUP(E$7/Paramètres!$B$6,0)) -> 3 | F25: =IF(F$7="","",ROUNDUP(F$7/Paramètres!$B$6,0)) -> 3 | G25: =IF(G$7="","",ROUNDUP(G$7/Paramètres!$B$6,0)) -> 1 | H25: =IF(H$7="","",ROUNDUP(H$7/Paramètres!$B$6,0)) -> 1 | I25: =IF(I$7="","",ROUNDUP(I$7/Paramètres!$B$6,0))
A26: =Paramètres!A36 -> Maître d'hôtel | B26: =Paramètres!E36 -> 1 à partir du seuil, 2 au-delà du second seuil. | C26: =IF(C$7="","",(C$7>=Paramètres!$B$7)*1+(C$7>=Paramètres!$B$8)*1) -> 1 | D26: =IF(D$7="","",(D$7>=Paramètres!$B$7)*1+(D$7>=Paramètres!$B$8)*1) -> 1 | E26: =IF(E$7="","",(E$7>=Paramètres!$B$7)*1+(E$7>=Paramètres!$B$8)*1) -> 1 | F26: =IF(F$7="","",(F$7>=Paramètres!$B$7)*1+(F$7>=Paramètres!$B$8)*1) -> 1 | G26: =IF(G$7="","",(G$7>=Paramètres!$B$7)*1+(G$7>=Paramètres!$B$8)*1) -> 0 | H26: =IF(H$7="","",(H$7>=Paramètres!$B$7)*1+(H$7>=Paramètres!$B$8)*1) -> 1 | I26: =IF(I$7="","",(I$7>=Paramètres!$B$7)*1+(I$7>=Paramètres!$B$8)*1)
A27: =Paramètres!A37 -> Serveurs (base) | B27: =Paramètres!E37 -> Couverts ÷ couverts par serveur, arrondi au supérieur. | C27: =IF(C$7="","",ROUNDUP(C$7/Paramètres!$B$5,0)) -> 4 | D27: =IF(D$7="","",ROUNDUP(D$7/Paramètres!$B$5,0)) -> 3 | E27: =IF(E$7="","",ROUNDUP(E$7/Paramètres!$B$5,0)) -> 4 | F27: =IF(F$7="","",ROUNDUP(F$7/Paramètres!$B$5,0)) -> 5 | G27: =IF(G$7="","",ROUNDUP(G$7/Paramètres!$B$5,0)) -> 1 | H27: =IF(H$7="","",ROUNDUP(H$7/Paramètres!$B$5,0)) -> 2 | I27: =IF(I$7="","",ROUNDUP(I$7/Paramètres!$B$5,0))
A28: =Paramètres!A38 -> Serveur de réserve | B28: =Paramètres!E38 -> 1 en C2 et en C3. | C28: =IF(C$7="","",IF(OR(C$10="C2",C$10="C3"),1,0)) -> 1 | D28: =IF(D$7="","",IF(OR(D$10="C2",D$10="C3"),1,0)) -> 1 | E28: =IF(E$7="","",IF(OR(E$10="C2",E$10="C3"),1,0)) -> 1 | F28: =IF(F$7="","",IF(OR(F$10="C2",F$10="C3"),1,0)) -> 1 | G28: =IF(G$7="","",IF(OR(G$10="C2",G$10="C3"),1,0)) -> 1 | H28: =IF(H$7="","",IF(OR(H$10="C2",H$10="C3"),1,0)) -> 1 | I28: =IF(I$7="","",IF(OR(I$10="C2",I$10="C3"),1,0))
A29: =Paramètres!A39 -> Serveurs pour salons supplémentaires | B29: =Paramètres!E39 -> En C3 : 1 par salon au-delà du premier. | C29: =IF(C$7="","",IF(C$10="C3",MAX(N(C$11)-1,0),0)) -> 0 | D29: =IF(D$7="","",IF(D$10="C3",MAX(N(D$11)-1,0),0)) -> 0 | E29: =IF(E$7="","",IF(E$10="C3",MAX(N(E$11)-1,0),0)) -> 0 | F29: =IF(F$7="","",IF(F$10="C3",MAX(N(F$11)-1,0),0)) -> 2 | G29: =IF(G$7="","",IF(G$10="C3",MAX(N(G$11)-1,0),0)) -> 0 | H29: =IF(H$7="","",IF(H$10="C3",MAX(N(H$11)-1,0),0)) -> 0 | I29: =IF(I$7="","",IF(I$10="C3",MAX(N(I$11)-1,0),0))
A30: =Paramètres!A40 -> Sommelier invité | B30: =Paramètres!E40 -> 1 par événement. | C30: =IF(C$7="","",1) -> 1 | D30: =IF(D$7="","",1) -> 1 | E30: =IF(E$7="","",1) -> 1 | F30: =IF(F$7="","",1) -> 1 | G30: =IF(G$7="","",1) -> 1 | H30: =IF(H$7="","",1) -> 1 | I30: =IF(I$7="","",1)
A31: =Paramètres!A41 -> Aide sommelier | B31: =Paramètres!E41 -> 1 à partir du seuil, 2 au-delà du second seuil. | C31: =IF(C$7="","",(C$7>=Paramètres!$B$9)*1+(C$7>=Paramètres!$B$10)*1) -> 1 | D31: =IF(D$7="","",(D$7>=Paramètres!$B$9)*1+(D$7>=Paramètres!$B$10)*1) -> 1 | E31: =IF(E$7="","",(E$7>=Paramètres!$B$9)*1+(E$7>=Paramètres!$B$10)*1) -> 1 | F31: =IF(F$7="","",(F$7>=Paramètres!$B$9)*1+(F$7>=Paramètres!$B$10)*1) -> 1 | G31: =IF(G$7="","",(G$7>=Paramètres!$B$9)*1+(G$7>=Paramètres!$B$10)*1) -> 0 | H31: =IF(H$7="","",(H$7>=Paramètres!$B$9)*1+(H$7>=Paramètres!$B$10)*1) -> 0 | I31: =IF(I$7="","",(I$7>=Paramètres!$B$9)*1+(I$7>=Paramètres!$B$10)*1)
A32: =Paramètres!A42 -> Plongeurs | B32: =Paramètres!E42 -> 1, puis 2 et 3 selon les seuils. | C32: =IF(C$7="","",1+(C$7>=Paramètres!$B$11)*1+(C$7>=Paramètres!$B$12)*1) -> 2 | D32: =IF(D$7="","",1+(D$7>=Paramètres!$B$11)*1+(D$7>=Paramètres!$B$12)*1) -> 2 | E32: =IF(E$7="","",1+(E$7>=Paramètres!$B$11)*1+(E$7>=Paramètres!$B$12)*1) -> 2 | F32: =IF(F$7="","",1+(F$7>=Paramètres!$B$11)*1+(F$7>=Paramètres!$B$12)*1) -> 2 | G32: =IF(G$7="","",1+(G$7>=Paramètres!$B$11)*1+(G$7>=Paramètres!$B$12)*1) -> 1 | H32: =IF(H$7="","",1+(H$7>=Paramètres!$B$11)*1+(H$7>=Paramètres!$B$12)*1) -> 1 | I32: =IF(I$7="","",1+(I$7>=Paramètres!$B$11)*1+(I$7>=Paramètres!$B$12)*1)
A33: =Paramètres!A43 -> Responsable de production (nous) | B33: =Paramètres!E43 -> 1, puis 2 à partir du seuil. | C33: =IF(C$7="","",1+(C$7>=Paramètres!$B$13)*1) -> 1 | D33: =IF(D$7="","",1+(D$7>=Paramètres!$B$13)*1) -> 1 | E33: =IF(E$7="","",1+(E$7>=Paramètres!$B$13)*1) -> 1 | F33: =IF(F$7="","",1+(F$7>=Paramètres!$B$13)*1) -> 1 | G33: =IF(G$7="","",1+(G$7>=Paramètres!$B$13)*1) -> 1 | H33: =IF(H$7="","",1+(H$7>=Paramètres!$B$13)*1) -> 1 | I33: =IF(I$7="","",1+(I$7>=Paramètres!$B$13)*1)
A34: =Paramètres!A44 -> Interlocuteur client (Ventes) | B34: =Paramètres!E44 -> 1 en C2 et en C3. | C34: =IF(C$7="","",IF(OR(C$10="C2",C$10="C3"),1,0)) -> 1 | D34: =IF(D$7="","",IF(OR(D$10="C2",D$10="C3"),1,0)) -> 1 | E34: =IF(E$7="","",IF(OR(E$10="C2",E$10="C3"),1,0)) -> 1 | F34: =IF(F$7="","",IF(OR(F$10="C2",F$10="C3"),1,0)) -> 1 | G34: =IF(G$7="","",IF(OR(G$10="C2",G$10="C3"),1,0)) -> 1 | H34: =IF(H$7="","",IF(OR(H$10="C2",H$10="C3"),1,0)) -> 1 | I34: =IF(I$7="","",IF(OR(I$10="C2",I$10="C3"),1,0))
A35: =Paramètres!A45 -> Accueil et vestiaire | B35: =Paramètres!E45 -> En C3 : 1, puis 2 à partir du seuil. | C35: =IF(C$7="","",IF(C$10="C3",1+(C$7>=Paramètres!$B$14)*1,0)) -> 0 | D35: =IF(D$7="","",IF(D$10="C3",1+(D$7>=Paramètres!$B$14)*1,0)) -> 0 | E35: =IF(E$7="","",IF(E$10="C3",1+(E$7>=Paramètres!$B$14)*1,0)) -> 0 | F35: =IF(F$7="","",IF(F$10="C3",1+(F$7>=Paramètres!$B$14)*1,0)) -> 1 | G35: =IF(G$7="","",IF(G$10="C3",1+(G$7>=Paramètres!$B$14)*1,0)) -> 0 | H35: =IF(H$7="","",IF(H$10="C3",1+(H$7>=Paramètres!$B$14)*1,0)) -> 0 | I35: =IF(I$7="","",IF(I$10="C3",1+(I$7>=Paramètres!$B$14)*1,0))
A36: =Paramètres!A46 -> Relations presse et invités (Marketing) | B36: =Paramètres!E46 -> 1 en C3. | C36: =IF(C$7="","",IF(C$10="C3",1,0)) -> 0 | D36: =IF(D$7="","",IF(D$10="C3",1,0)) -> 0 | E36: =IF(E$7="","",IF(E$10="C3",1,0)) -> 0 | F36: =IF(F$7="","",IF(F$10="C3",1,0)) -> 1 | G36: =IF(G$7="","",IF(G$10="C3",1,0)) -> 0 | H36: =IF(H$7="","",IF(H$10="C3",1,0)) -> 0 | I36: =IF(I$7="","",IF(I$10="C3",1,0))
A37: =Paramètres!A47 -> Photographe | B37: =Paramètres!E47 -> 1 en C3 (prévu dans les trois options de lancement du Marketing). | C37: =IF(C$7="","",IF(C$10="C3",1,0)) -> 0 | D37: =IF(D$7="","",IF(D$10="C3",1,0)) -> 0 | E37: =IF(E$7="","",IF(E$10="C3",1,0)) -> 0 | F37: =IF(F$7="","",IF(F$10="C3",1,0)) -> 1 | G37: =IF(G$7="","",IF(G$10="C3",1,0)) -> 0 | H37: =IF(H$7="","",IF(H$10="C3",1,0)) -> 0 | I37: =IF(I$7="","",IF(I$10="C3",1,0))
A38: =Paramètres!A48 -> Vidéaste | B38: =Paramètres!E48 -> 1 en C3 (idem). | C38: =IF(C$7="","",IF(C$10="C3",1,0)) -> 0 | D38: =IF(D$7="","",IF(D$10="C3",1,0)) -> 0 | E38: =IF(E$7="","",IF(E$10="C3",1,0)) -> 0 | F38: =IF(F$7="","",IF(F$10="C3",1,0)) -> 1 | G38: =IF(G$7="","",IF(G$10="C3",1,0)) -> 0 | H38: =IF(H$7="","",IF(H$10="C3",1,0)) -> 0 | I38: =IF(I$7="","",IF(I$10="C3",1,0))
A39: =Paramètres!A49 -> Logistique d'accès | B39: =Paramètres!E49 -> 1 si le lieu exige une logistique d'accès particulière (ex. bateaux). | C39: =IF(C$7="","",IF(C$12="Oui",1,0)) -> 0 | D39: =IF(D$7="","",IF(D$12="Oui",1,0)) -> 0 | E39: =IF(E$7="","",IF(E$12="Oui",1,0)) -> 0 | F39: =IF(F$7="","",IF(F$12="Oui",1,0)) -> 0 | G39: =IF(G$7="","",IF(G$12="Oui",1,0)) -> 0 | H39: =IF(H$7="","",IF(H$12="Oui",1,0)) -> 0 | I39: =IF(I$7="","",IF(I$12="Oui",1,0))
A40: Total, chef compris | C40: =IF(C7="","",SUM(C24:C39)) -> 16 | D40: =IF(D7="","",SUM(D24:D39)) -> 14 | E40: =IF(E7="","",SUM(E24:E39)) -> 16 | F40: =IF(F7="","",SUM(F24:F39)) -> 23 | G40: =IF(G7="","",SUM(G24:G39)) -> 8 | H40: =IF(H7="","",SUM(H24:H39)) -> 10 | I40: =IF(I7="","",SUM(I24:I39))
A41: dont postes de salle fournis par le restaurant | C41: =IF(C7="","",IF(C13="Restaurant",SUMPRODUCT(C24:C39,Paramètres!$D$34:$D$49),0)) -> 0 | D41: =IF(D7="","",IF(D13="Restaurant",SUMPRODUCT(D24:D39,Paramètres!$D$34:$D$49),0)) -> 0 | E41: =IF(E7="","",IF(E13="Restaurant",SUMPRODUCT(E24:E39,Paramètres!$D$34:$D$49),0)) -> 0 | F41: =IF(F7="","",IF(F13="Restaurant",SUMPRODUCT(F24:F39,Paramètres!$D$34:$D$49),0)) -> 0 | G41: =IF(G7="","",IF(G13="Restaurant",SUMPRODUCT(G24:G39,Paramètres!$D$34:$D$49),0)) -> 0 | H41: =IF(H7="","",IF(H13="Restaurant",SUMPRODUCT(H24:H39,Paramètres!$D$34:$D$49),0)) -> 0 | I41: =IF(I7="","",IF(I13="Restaurant",SUMPRODUCT(I24:I39,Paramètres!$D$34:$D$49),0))
A42: Total à mobiliser par nous | C42: =IF(C7="","",C40-C41) -> 16 | D42: =IF(D7="","",D40-D41) -> 14 | E42: =IF(E7="","",E40-E41) -> 16 | F42: =IF(F7="","",F40-F41) -> 23 | G42: =IF(G7="","",G40-G41) -> 8 | H42: =IF(H7="","",H40-H41) -> 10 | I42: =IF(I7="","",I40-I41)
A43: Heures de travail (à mobiliser par nous) | B43: reste à 0 tant que les heures ne sont pas saisies | C43: =IF(C7="","",SUMPRODUCT(C24:C39,Paramètres!$B$34:$B$49)-IF(C13="Restaurant",SUMPRODUCT(C24:C39,Paramètres!$B$34:$B$49,Paramètres!$D$34:$D$49),0)) -> 0 | D43: =IF(D7="","",SUMPRODUCT(D24:D39,Paramètres!$B$34:$B$49)-IF(D13="Restaurant",SUMPRODUCT(D24:D39,Paramètres!$B$34:$B$49,Paramètres!$D$34:$D$49),0)) -> 0 | E43: =IF(E7="","",SUMPRODUCT(E24:E39,Paramètres!$B$34:$B$49)-IF(E13="Restaurant",SUMPRODUCT(E24:E39,Paramètres!$B$34:$B$49,Paramètres!$D$34:$D$49),0)) -> 0 | F43: =IF(F7="","",SUMPRODUCT(F24:F39,Paramètres!$B$34:$B$49)-IF(F13="Restaurant",SUMPRODUCT(F24:F39,Paramètres!$B$34:$B$49,Paramètres!$D$34:$D$49),0)) -> 0 | G43: =IF(G7="","",SUMPRODUCT(G24:G39,Paramètres!$B$34:$B$49)-IF(G13="Restaurant",SUMPRODUCT(G24:G39,Paramètres!$B$34:$B$49,Paramètres!$D$34:$D$49),0)) -> 0 | H43: =IF(H7="","",SUMPRODUCT(H24:H39,Paramètres!$B$34:$B$49)-IF(H13="Restaurant",SUMPRODUCT(H24:H39,Paramètres!$B$34:$B$49,Paramètres!$D$34:$D$49),0)) -> 0 | I43: =IF(I7="","",SUMPRODUCT(I24:I39,Paramètres!$B$34:$B$49)-IF(I13="Restaurant",SUMPRODUCT(I24:I39,Paramètres!$B$34:$B$49,Paramètres!$D$34:$D$49),0))
...

Sheet Paramètres
A1: Paramètres du calculateur
A2: Cellules jaunes modifiables. Chaque valeur porte sa nature et sa source.
A4: Paramètre | B4: Valeur | C4: Nature | D4: Source / justification
A5: Couverts par serveur | B5: 7 | C5: P | D5: Repères : 1 serveur pour 10-12 convives à l'assiette, 1 pour 8-10 en VIP ou menu à plusieurs services (guides de traiteurs, pebb.io, workstaff.app) ; jusqu'à 1 pour 5 en restaurant gastronomique (modelesdebusinessplan.com). Haut de fourchette retenu pour 6 à 9 services.
A6: Couverts par membre de brigade (hors chef) | B6: 10 | C6: P | D6: Repère traiteur : 3 cuisiniers pour 50 convives (workstaff.app), jugé insuffisant pour un menu gastronomique : à confirmer avec le chef.
A7: Seuil : 1 maître d'hôtel à partir de (couverts) | B7: 9 | C7: P | D7: En dessous, le sommelier tient la salle.
A8: Seuil : 2e maître d'hôtel à partir de | B8: 41 | C8: P | D8: Classe T4 haute.
A9: Seuil : 1 aide sommelier à partir de | B9: 20 | C9: P | D9: Accords vins et accords jus servis en parallèle (offre du Produit).
A10: Seuil : 2e aide sommelier à partir de | B10: 41 | C10: P
A11: Seuil : 2e plongeur à partir de | B11: 17 | C11: P | D11: Repère : 2 personnes dès qu'un lave-vaisselle tourne, une charge, une décharge (ellenskitchen.com).
A12: Seuil : 3e plongeur à partir de | B12: 41 | C12: P
A13: Seuil : 2e responsable de production à partir de | B13: 31 | C13: P | D13: Classe T4.
A14: Seuil : 2e hôte d'accueil (C3) à partir de | B14: 41 | C14: P
A17: Classes de taille
A18: Classe | B18: Jusqu'à (couverts) | C18: Libellé | D18: Dans le périmètre ?
A19: T1 | B19: 8 | C19: Intime | D19: Oui
A20: T2 | B20: 16 | C20: Table | D20: Oui
A21: T3 | B21: 30 | C21: Salle | D21: Oui : cœur de l'offre
A22: T4 | B22: 60 | C22: Grand | D22: Oui, au cas par cas
A23: T5 | B23: 100000 | C23: Très grand | D23: Non à ce stade (décision Direction)
A26: Niveaux de criticité
A27: Niveau | B27: Délai minimum (semaines) | C27: Libellé | D27: Critères (il suffit d'en remplir un)
A28: C1 | B28: 6 | C28: Standard | D28: Soirée récurrente vendue à la place ; chef et lieu déjà connus ; pas de presse. Délai : plan des pilotes du Produit (ventes à S-6).
A29: C2 | B29: 8 | C29: Premium | D29: Client-payeur unique sous contrat ; chef étoilé ou étranger ; première collaboration avec un lieu ou un chef ; produits importés. Délai : plan des pilotes (lieux et chefs à S-10, contrats à S-8).
A30: C3 | B30: 10 | C30: Signature | D30: Presse, influenceurs ou célébrités ; maison de luxe sous contrat cadre ; lieu atypique ; soirée de lancement. Délai : 10 semaines et plus.
A32: Rôles : heures et coûts (à renseigner à réception des devis)
A33: Rôle | B33: Heures par personne (H) | C33: Coût horaire chargé (€) (H) | D33: Poste de salle (1 = oui) | E33: Règle de calcul
A34: Chef invité | D34: 0 | E34: 1 par événement. Son cachet n'est pas horaire : le saisir à part avec la Finance (donnée n° 2).
A35: Brigade (second, commis) | D35: 0 | E35: Couverts ÷ couverts par membre de brigade, arrondi au supérieur.
A36: Maître d'hôtel | D36: 1 | E36: 1 à partir du seuil, 2 au-delà du second seuil.
A37: Serveurs (base) | D37: 1 | E37: Couverts ÷ couverts par serveur, arrondi au supérieur.
A38: Serveur de réserve | D38: 1 | E38: 1 en C2 et en C3.
A39: Serveurs pour salons supplémentaires | D39: 1 | E39: En C3 : 1 par salon au-delà du premier.
A40: Sommelier invité | D40: 0 | E40: 1 par événement.
A41: Aide sommelier | D41: 0 | E41: 1 à partir du seuil, 2 au-delà du second seuil.
A42: Plongeurs | D42: 0 | E42: 1, puis 2 et 3 selon les seuils.
A43: Responsable de production (nous) | D43: 0 | E43: 1, puis 2 à partir du seuil.
A44: Interlocuteur client (Ventes) | D44: 0 | E44: 1 en C2 et en C3.
A45: Accueil et vestiaire | D45: 0 | E45: En C3 : 1, puis 2 à partir du seuil.
... A49: Logistique d'accès | D49: 0 | E49: 1 si le lieu exige une logistique d'accès particulière (ex. bateaux).
...
